Workbook

Sheet Product_Master
A1: Product_ID | B1: Product_Name | C1: Category | D1: Pack_Size_g | E1: Shelf_Life_Days
A2: P001 | B2: Country Breakfast Sausage | C2: Sausage | D2: 400 | E2: 12
A3: P002 | B3: Herb Chicken Bites | C3: Chicken | D3: 350 | E3: 10
A4: P003 | B4: Veggie Breakfast Patties | C4: Plant-Based | D4: 300 | E4: 14
A5: P004 | B5: Smoky Beef Bites | C5: Beef | D5: 400 | E5: 9
A6: P005 | B6: Family Breakfast Pack | C6: Mixed Breakfast | D6: 600 | E6: 11

Sheet Customer_Master
A1: Customer_ID | B1: Customer_Name | C1: Channel
A2: C001 | B2: MarketOne | C2: Supermarket
A3: C002 | B3: FreshBasket | C3: Supermarket
A4: C003 | B4: GreenMart | C4: Supermarket
A5: C004 | B5: TownFoods | C5: Supermarket

Sheet Production_Line_Master
A1: Line_ID | B1: Line_Name | C1: Packs_Per_Hour | D1: Available_Hours_Week | E1: Max_Weekly_Capacity
A2: L01 | B2: Sausage Line | C2: 1800 | D2: 40 | E2: 72000
A3: L02 | B3: Bites Line | C3: 1500 | D3: 40 | E3: 60000
A4: L03 | B4: Patties & Mixed Line | C4: 1200 | D4: 35 | E4: 42000

Sheet Product_Line_Map
A1: Product_ID | B1: Line_ID
A2: P001 | B2: L01
A3: P002 | B3: L02
A4: P004 | B4: L02
A5: P003 | B5: L03
A6: P005 | B6: L03

Sheet Material_Master
A1: Material_ID | B1: Material_Name | C1: Material_Type | D1: Unit_of_Measure
A2: M001 | B2: Sausage Meat Mix | C2: Ingredient | D2: kg
A3: M002 | B3: Chicken Meat | C3: Ingredient | D3: kg
A4: M003 | B4: Plant Protein Mix | C4: Ingredient | D4: kg
A5: M004 | B5: Beef Meat | C5: Ingredient | D5: kg
A6: M005 | B6: Breakfast Protein Mix | C6: Ingredient | D6: kg
A7: M006 | B7: Seasoning Mix | C7: Ingredient | D7: kg
A8: M007 | B8: Packaging Tray | C8: Packaging | D8: each
A9: M008 | B9: Product Label | C9: Packaging | D9: each

Sheet BOM
A1: Product_ID | B1: Material_ID | C1: Qty_Per_Pack
A2: P001 | B2: M001 | C2: 0.35
A3: P001 | B3: M006 | C3: 0.01
A4: P001 | B4: M007 | C4: 1
A5: P001 | B5: M008 | C5: 1
A6: P002 | B6: M002 | C6: 0.3
A7: P002 | B7: M006 | C7: 0.008
A8: P002 | B8: M007 | C8: 1
A9: P002 | B9: M008 | C9: 1
A10: P003 | B10: M003 | C10: 0.25
A11: P003 | B11: M006 | C11: 0.006
A12: P003 | B12: M007 | C12: 1
A13: P003 | B13: M008 | C13: 1
... A21: P005 | B21: M008 | C21: 1

Sheet Forecast
A1: Week_Start | B1: Customer_ID | C1: Product_ID | D1: Forecast_Qty
A2: 46027 | B2: C001 | C2: P001 | D2: 5200
A3: 46027 | B3: C001 | C3: P002 | D3: 4100
A4: 46027 | B4: C002 | C4: P001 | D4: 3400
A5: 46027 | B5: C003 | C5: P003 | D5: 2800
A6: 46027 | B6: C004 | C6: P004 | D6: 2600

Sheet Actual_Orders
A1: Week_Start | B1: Customer_ID | C1: Product_ID | D1: Actual_Order_Qty
A2: 46027 | B2: C001 | C2: P001 | D2: 5600
A3: 46027 | B3: C001 | C3: P002 | D3: 3900
A4: 46027 | B4: C002 | C4: P001 | D4: 3600
A5: 46027 | B5: C003 | C5: P003 | D5: 3100
A6: 46027 | B6: C004 | C6: P004 | D6: 2500

Sheet Finished_Goods_Inventory
A1: Week_Start | B1: Product_ID | C1: Physical_Stock | D1: Allocated_Stock | E1: Blocked_Stock
A2: 46027 | B2: P001 | C2: 7200 | D2: 1200 | E2: 200
A3: 46027 | B3: P002 | C3: 6100 | D3: 900 | E3: 100
A4: 46027 | B4: P003 | C4: 4800 | D4: 600 | E4: 0
A5: 46027 | B5: P004 | C5: 5200 | D5: 800 | E5: 300
A6: 46027 | B6: P005 | C6: 3900 | D6: 500 | E6: 100

Sheet Production_Plan
A1: Week_Start | B1: Product_ID | C1: Planned_Production_Qty
A2: 46027 | B2: P001 | C2: 8500
A3: 46027 | B3: P002 | C3: 7200
A4: 46027 | B4: P003 | C4: 5200
A5: 46027 | B5: P004 | C5: 6100
A6: 46027 | B6: P005 | C6: 4700

Sheet Production_Actuals
A1: Week_Start | B1: Product_ID | C1: Actual_Production_Qty
A2: 46027 | B2: P001 | C2: 8300
A3: 46027 | B3: P002 | C3: 6800
A4: 46027 | B4: P003 | C4: 5100
A5: 46027 | B5: P004 | C5: 5700
A6: 46027 | B6: P005 | C6: 4600

Sheet Raw_Material_Inventory
A1: Week_Start | B1: Material_ID | C1: Available_Qty
A2: 46027 | B2: M001 | C2: 4200
A3: 46027 | B3: M002 | C3: 3100
A4: 46027 | B4: M003 | C4: 1900
A5: 46027 | B5: M004 | C5: 2300
A6: 46027 | B6: M005 | C6: 2800
A7: 46027 | B7: M006 | C7: 420
A8: 46027 | B8: M007 | C8: 31000
A9: 46027 | B9: M008 | C9: 32000

Sheet Weekly_Capacity
A1: Week_Start | B1: Line_ID | C1: Scheduled_Hours | D1: Planned_Downtime_Hours | E1: Available_Hours
A2: 46027 | B2: L01 | C2: 40 | D2: 2 | E2: 38
A3: 46027 | B3: L02 | C3: 40 | D3: 5 | E3: 35
A4: 46027 | B4: L03 | C4: 35 | D4: 0 | E4: 35

Sheet Demand_Assumptions
A1: Customer_ID | B1: Product_ID | C1: Baseline_Weekly_Qty
A2: C001 | B2: P001 | C2: 5200
A3: C001 | B3: P002 | C3: 4100
A4: C001 | B4: P003 | C4: 3300
A5: C001 | B5: P004 | C5: 3600
A6: C001 | B6: P005 | C6: 2800
A7: C002 | B7: P001 | C7: 3400
A8: C002 | B8: P002 | C8: 3200
A9: C002 | B9: P003 | C9: 2600
A10: C002 | B10: P004 | C10: 2900
A11: C002 | B11: P005 | C11: 2200
A12: C003 | B12: P001 | C12: 3000
A13: C003 | B13: P002 | C13: 2700
... A21: C004 | B21: P005 | C21: 1800

Sheet Scenario_Assumptions
A1: Scenario_ID | B1: Week_Start | C1: Customer_ID | D1: Product_ID | E1: Scenario_Type | F1: Scenario_Value
A2: S001 | B2: 46097 | C2: C001 | D2: P001 | E2: Promotion_Demand_Spike | F2: 1.35
A3: S002 | B3: 46181 | C3: C002 | D3: P004 | E3: Under_Forecast | F3: 1.25
A4: S003 | B4: 46223 | C4: C003 | D4: P003 | E4: Over_Forecast | F4: 0.72
A5: S004 | B5: 46279 | C5: ALL | D5: P002 | E5: Material_Shortage | F5: 0.65
A6: S005 | B6: 46328 | C6: ALL | D6: P004 | E6: Capacity_Reduction | F6: 0.7
A7: S006 | B7: 46363 | C7: ALL | D7: P005 | E7: Production_Shortfall | F7: 0.7

Sheet Calendar_Weeks
A1: Week_Start
A2: =DATE(2026,1,5) -> 46027
A3: =A2+7 -> 46034
A4: =A3+7 -> 46041
A5: =A4+7 -> 46048
A6: =A5+7 -> 46055
A7: =A6+7 -> 46062
A8: =A7+7 -> 46069
A9: =A8+7 -> 46076
A10: =A9+7 -> 46083
A11: =A10+7 -> 46090
A12: =A11+7 -> 46097
A13: =A12+7 -> 46104
A14: =A13+7 -> 46111
... A53: =A52+7 -> 46384

Sheet Demand_Base
A1: Week_Start | B1: Customer_ID | C1: Product_ID | D1: Baseline_Weekly_Qty | E1: Seasonality_Factor | F1: Natural_Variation_Factor | G1: Normal_Demand_Qty | H1: Forecast_Factor | I1: Forecast_Qty | J1: Demand_Scenario | K1: Actual_Order_Qty | L1: Forecast_Error | M1: Forecast_Variance_% | N1: Absolute_Forecast_Error
A2: {=INDEX(tblWeeks[Week_Start],INT((ROW()-2)/20)+1)} -> 46027 | B2: {=INDEX(tblDemandAssumptions[Customer_ID],MOD(ROW()-2,20)+1)} -> C001 | C2: {=INDEX(tblDemandAssumptions[Product_ID],MOD(ROW()-2,20)+1)} -> P001 | D2: {=INDEX(tblDemandAssumptions[Baseline_Weekly_Qty],MOD(ROW()-2,20)+1)} -> 5200 | E2: =IF(MONTH(A2)<=2,0.95,IF(MONTH(A2)<=4,1,IF(MONTH(A2)<=6,1.05,IF(MONTH(A2)<=8,1.1,IF(MONTH(A2)<=10,1,IF(MONTH(A2)=11,1.05,1.2)))))) -> 0.95 | F2: 0.98 | G2: =ROUND(D2*E2*F2,0) -> 4841 | H2: 1.02 | I2: =ROUND(D2*E2*H2,0) -> 5039 | J2: =IF(AND(A2=DATE(2026,3,16),B2="C001",C2="P001"),"Promotion_Demand_Spike",IF(AND(A2=DATE(2026,6,8),B2="C002",C2="P004"),"Under_Forecast",IF(AND(A2=DATE(2026,7,20),B2="C003",C2="P003"),"Over_Forecast","Normal"))) -> Normal | K2: =IF(J2="Promotion_Demand_Spike",ROUND(G2*1.35,0),IF(J2="Under_Forecast",ROUND(I2*1.25,0),IF(J2="Over_Forecast",ROUND(I2*0.72,0),G2))) -> 4841 | L2: =K2-I2 -> -198 | M2: =IF(I2=0,0,L2/I2) -> -0.039293511 | N2: =ABS(L2) -> 198
A3: {=INDEX(tblWeeks[Week_Start],INT((ROW()-2)/20)+1)} -> 46027 | B3: {=INDEX(tblDemandAssumptions[Customer_ID],MOD(ROW()-2,20)+1)} -> C001 | C3: {=INDEX(tblDemandAssumptions[Product_ID],MOD(ROW()-2,20)+1)} -> P002 | D3: {=INDEX(tblDemandAssumptions[Baseline_Weekly_Qty],MOD(ROW()-2,20)+1)} -> 4100 | E3: =IF(MONTH(A3)<=2,0.95,IF(MONTH(A3)<=4,1,IF(MONTH(A3)<=6,1.05,IF(MONTH(A3)<=8,1.1,IF(MONTH(A3)<=10,1,IF(MONTH(A3)=11,1.05,1.2)))))) -> 0.95 | F3: 1 | G3: =ROUND(D3*E3*F3,0) -> 3895 | H3: 0.98 | I3: =ROUND(D3*E3*H3,0) -> 3817 | J3: =IF(AND(A3=DATE(2026,3,16),B3="C001",C3="P001"),"Promotion_Demand_Spike",IF(AND(A3=DATE(2026,6,8),B3="C002",C3="P004"),"Under_Forecast",IF(AND(A3=DATE(2026,7,20),B3="C003",C3="P003"),"Over_Forecast","Normal"))) -> Normal | K3: =IF(J3="Promotion_Demand_Spike",ROUND(G3*1.35,0),IF(J3="Under_Forecast",ROUND(I3*1.25,0),IF(J3="Over_Forecast",ROUND(I3*0.72,0),G3))) -> 3895 | L3: =K3-I3 -> 78 | M3: =IF(I3=0,0,L3/I3) -> 0.020434897 | N3: =ABS(L3) -> 78
A4: {=INDEX(tblWeeks[Week_Start],INT((ROW()-2)/20)+1)} -> 46027 | B4: {=INDEX(tblDemandAssumptions[Customer_ID],MOD(ROW()-2,20)+1)} -> C001 | C4: {=INDEX(tblDemandAssumptions[Product_ID],MOD(ROW()-2,20)+1)} -> P003 | D4: {=INDEX(tblDemandAssumptions[Baseline_Weekly_Qty],MOD(ROW()-2,20)+1)} -> 3300 | E4: =IF(MONTH(A4)<=2,0.95,IF(MONTH(A4)<=4,1,IF(MONTH(A4)<=6,1.05,IF(MONTH(A4)<=8,1.1,IF(MONTH(A4)<=10,1,IF(MONTH(A4)=11,1.05,1.2)))))) -> 0.95 | F4: 1.01 | G4: =ROUND(D4*E4*F4,0) -> 3166 | H4: 1.01 | I4: =ROUND(D4*E4*H4,0) -> 3166 | J4: =IF(AND(A4=DATE(2026,3,16),B4="C001",C4="P001"),"Promotion_Demand_Spike",IF(AND(A4=DATE(2026,6,8),B4="C002",C4="P004"),"Under_Forecast",IF(AND(A4=DATE(2026,7,20),B4="C003",C4="P003"),"Over_Forecast","Normal"))) -> Normal | K4: =IF(J4="Promotion_Demand_Spike",ROUND(G4*1.35,0),IF(J4="Under_Forecast",ROUND(I4*1.25,0),IF(J4="Over_Forecast",ROUND(I4*0.72,0),G4))) -> 3166 | L4: =K4-I4 -> 0 | M4: =IF(I4=0,0,L4/I4) -> 0 | N4: =ABS(L4) -> 0
A5: {=INDEX(tblWeeks[Week_Start],INT((ROW()-2)/20)+1)} -> 46027 | B5: {=INDEX(tblDemandAssumptions[Customer_ID],MOD(ROW()-2,20)+1)} -> C001 | C5: {=INDEX(tblDemandAssumptions[Product_ID],MOD(ROW()-2,20)+1)} -> P004 | D5: {=INDEX(tblDemandAssumptions[Baseline_Weekly_Qty],MOD(ROW()-2,20)+1)} -> 3600 | E5: =IF(MONTH(A5)<=2,0.95,IF(MONTH(A5)<=4,1,IF(MONTH(A5)<=6,1.05,IF(MONTH(A5)<=8,1.1,IF(MONTH(A5)<=10,1,IF(MONTH(A5)=11,1.05,1.2)))))) -> 0.95 | F5: 0.95 | G5: =ROUND(D5*E5*F5,0) -> 3249 | H5: 0.96 | I5: =ROUND(D5*E5*H5,0) -> 3283 | J5: =IF(AND(A5=DATE(2026,3,16),B5="C001",C5="P001"),"Promotion_Demand_Spike",IF(AND(A5=DATE(2026,6,8),B5="C002",C5="P004"),"Under_Forecast",IF(AND(A5=DATE(2026,7,20),B5="C003",C5="P003"),"Over_Forecast","Normal"))) -> Normal | K5: =IF(J5="Promotion_Demand_Spike",ROUND(G5*1.35,0),IF(J5="Under_Forecast",ROUND(I5*1.25,0),IF(J5="Over_Forecast",ROUND(I5*0.72,0),G5))) -> 3249 | L5: =K5-I5 -> -34 | M5: =IF(I5=0,0,L5/I5) -> -0.010356381 | N5: =ABS(L5) -> 34
A6: {=INDEX(tblWeeks[Week_Start],INT((ROW()-2)/20)+1)} -> 46027 | B6: {=INDEX(tblDemandAssumptions[Customer_ID],MOD(ROW()-2,20)+1)} -> C001 | C6: {=INDEX(tblDemandAssumptions[Product_ID],MOD(ROW()-2,20)+1)} -> P005 | D6: {=INDEX(tblDemandAssumptions[Baseline_Weekly_Qty],MOD(ROW()-2,20)+1)} -> 2800 | E6: =IF(MONTH(A6)<=2,0.95,IF(MONTH(A6)<=4,1,IF(MONTH(A6)<=6,1.05,IF(MONTH(A6)<=8,1.1,IF(MONTH(A6)<=10,1,IF(MONTH(A6)=11,1.05,1.2)))))) -> 0.95 | F6: 1.02 | G6: =ROUND(D6*E6*F6,0) -> 2713 | H6: 1.04 | I6: =ROUND(D6*E6*H6,0) -> 2766 | J6: =IF(AND(A6=DATE(2026,3,16),B6="C001",C6="P001"),"Promotion_Demand_Spike",IF(AND(A6=DATE(2026,6,8),B6="C002",C6="P004"),"Under_Forecast",IF(AND(A6=DATE(2026,7,20),B6="C003",C6="P003"),"Over_Forecast","Normal"))) -> Normal | K6: =IF(J6="Promotion_Demand_Spike",ROUND(G6*1.35,0),IF(J6="Under_Forecast",ROUND(I6*1.25,0),IF(J6="Over_Forecast",ROUND(I6*0.72,0),G6))) -> 2713 | L6: =K6-I6 -> -53 | M6: =IF(I6=0,0,L6/I6) -> -0.019161244 | N6: =ABS(L6) -> 53
A7: {=INDEX(tblWeeks[Week_Start],INT((ROW()-2)/20)+1)} -> 46027 | B7: {=INDEX(tblDemandAssumptions[Customer_ID],MOD(ROW()-2,20)+1)} -> C002 | C7: {=INDEX(tblDemandAssumptions[Product_ID],MOD(ROW()-2,20)+1)} -> P001 | D7: {=INDEX(tblDemandAssumptions[Baseline_Weekly_Qty],MOD(ROW()-2,20)+1)} -> 3400 | E7: =IF(MONTH(A7)<=2,0.95,IF(MONTH(A7)<=4,1,IF(MONTH(A7)<=6,1.05,IF(MONTH(A7)<=8,1.1,IF(MONTH(A7)<=10,1,IF(MONTH(A7)=11,1.05,1.2)))))) -> 0.95 | F7: 1.02 | G7: =ROUND(D7*E7*F7,0) -> 3295 | H7: 1 | I7: =ROUND(D7*E7*H7,0) -> 3230 | J7: =IF(AND(A7=DATE(2026,3,16),B7="C001",C7="P001"),"Promotion_Demand_Spike",IF(AND(A7=DATE(2026,6,8),B7="C002",C7="P004"),"Under_Forecast",IF(AND(A7=DATE(2026,7,20),B7="C003",C7="P003"),"Over_Forecast","Normal"))) -> Normal | K7: =IF(J7="Promotion_Demand_Spike",ROUND(G7*1.35,0),IF(J7="Under_Forecast",ROUND(I7*1.25,0),IF(J7="Over_Forecast",ROUND(I7*0.72,0),G7))) -> 3295 | L7: =K7-I7 -> 65 | M7: =IF(I7=0,0,L7/I7) -> 0.020123839 | N7: =ABS(L7) -> 65
A8: {=INDEX(tblWeeks[Week_Start],INT((ROW()-2)/20)+1)} -> 46027 | B8: {=INDEX(tblDemandAssumptions[Customer_ID],MOD(ROW()-2,20)+1)} -> C002 | C8: {=INDEX(tblDemandAssumptions[Product_ID],MOD(ROW()-2,20)+1)} -> P002 | D8: {=INDEX(tblDemandAssumptions[Baseline_Weekly_Qty],MOD(ROW()-2,20)+1)} -> 3200 | E8: =IF(MONTH(A8)<=2,0.95,IF(MONTH(A8)<=4,1,IF(MONTH(A8)<=6,1.05,IF(MONTH(A8)<=8,1.1,IF(MONTH(A8)<=10,1,IF(MONTH(A8)=11,1.05,1.2)))))) -> 0.95 | F8: 1.03 | G8: =ROUND(D8*E8*F8,0) -> 3131 | H8: 1 | I8: =ROUND(D8*E8*H8,0) -> 3040 | J8: =IF(AND(A8=DATE(2026,3,16),B8="C001",C8="P001"),"Promotion_Demand_Spike",IF(AND(A8=DATE(2026,6,8),B8="C002",C8="P004"),"Under_Forecast",IF(AND(A8=DATE(2026,7,20),B8="C003",C8="P003"),"Over_Forecast","Normal"))) -> Normal | K8: =IF(J8="Promotion_Demand_Spike",ROUND(G8*1.35,0),IF(J8="Under_Forecast",ROUND(I8*1.25,0),IF(J8="Over_Forecast",ROUND(I8*0.72,0),G8))) -> 3131 | L8: =K8-I8 -> 91 | M8: =IF(I8=0,0,L8/I8) -> 0.029934211 | N8: =ABS(L8) -> 91
A9: {=INDEX(tblWeeks[Week_Start],INT((ROW()-2)/20)+1)} -> 46027 | B9: {=INDEX(tblDemandAssumptions[Customer_ID],MOD(ROW()-2,20)+1)} -> C002 | C9: {=INDEX(tblDemandAssumptions[Product_ID],MOD(ROW()-2,20)+1)} -> P003 | D9: {=INDEX(tblDemandAssumptions[Baseline_Weekly_Qty],MOD(ROW()-2,20)+1)} -> 2600 | E9: =IF(MONTH(A9)<=2,0.95,IF(MONTH(A9)<=4,1,IF(MONTH(A9)<=6,1.05,IF(MONTH(A9)<=8,1.1,IF(MONTH(A9)<=10,1,IF(MONTH(A9)=11,1.05,1.2)))))) -> 0.95 | F9: 1 | G9: =ROUND(D9*E9*F9,0) -> 2470 | H9: 1.04 | I9: =ROUND(D9*E9*H9,0) -> 2569 | J9: =IF(AND(A9=DATE(2026,3,16),B9="C001",C9="P001"),"Promotion_Demand_Spike",IF(AND(A9=DATE(2026,6,8),B9="C002",C9="P004"),"Under_Forecast",IF(AND(A9=DATE(2026,7,20),B9="C003",C9="P003"),"Over_Forecast","Normal"))) -> Normal | K9: =IF(J9="Promotion_Demand_Spike",ROUND(G9*1.35,0),IF(J9="Under_Forecast",ROUND(I9*1.25,0),IF(J9="Over_Forecast",ROUND(I9*0.72,0),G9))) -> 2470 | L9: =K9-I9 -> -99 | M9: =IF(I9=0,0,L9/I9) -> -0.038536395 | N9: =ABS(L9) -> 99
A10: {=INDEX(tblWeeks[Week_Start],INT((ROW()-2)/20)+1)} -> 46027 | B10: {=INDEX(tblDemandAssumptions[Customer_ID],MOD(ROW()-2,20)+1)} -> C002 | C10: {=INDEX(tblDemandAssumptions[Product_ID],MOD(ROW()-2,20)+1)} -> P004 | D10: {=INDEX(tblDemandAssumptions[Baseline_Weekly_Qty],MOD(ROW()-2,20)+1)} -> 2900 | E10: =IF(MONTH(A10)<=2,0.95,IF(MONTH(A10)<=4,1,IF(MONTH(A10)<=6,1.05,IF(MONTH(A10)<=8,1.1,IF(MONTH(A10)<=10,1,IF(MONTH(A10)=11,1.05,1.2)))))) -> 0.95 | F10: 1.05 | G10: =ROUND(D10*E10*F10,0) -> 2893 | H10: 1.01 | I10: =ROUND(D10*E10*H10,0) -> 2783 | J10: =IF(AND(A10=DATE(2026,3,16),B10="C001",C10="P001"),"Promotion_Demand_Spike",IF(AND(A10=DATE(2026,6,8),B10="C002",C10="P004"),"Under_Forecast",IF(AND(A10=DATE(2026,7,20),B10="C003",C10="P003"),"Over_Forecast","Normal"))) -> Normal | K10: =IF(J10="Promotion_Demand_Spike",ROUND(G10*1.35,0),IF(J10="Under_Forecast",ROUND(I10*1.25,0),IF(J10="Over_Forecast",ROUND(I10*0.72,0),G10))) -> 2893 | L10: =K10-I10 -> 110 | M10: =IF(I10=0,0,L10/I10) -> 0.039525692 | N10: =ABS(L10) -> 110
A11: {=INDEX(tblWeeks[Week_Start],INT((ROW()-2)/20)+1)} -> 46027 | B11: {=INDEX(tblDemandAssumptions[Customer_ID],MOD(ROW()-2,20)+1)} -> C002 | C11: {=INDEX(tblDemandAssumptions[Product_ID],MOD(ROW()-2,20)+1)} -> P005 | D11: {=INDEX(tblDemandAssumptions[Baseline_Weekly_Qty],MOD(ROW()-2,20)+1)} -> 2200 | E11: =IF(MONTH(A11)<=2,0.95,IF(MONTH(A11)<=4,1,IF(MONTH(A11)<=6,1.05,IF(MONTH(A11)<=8,1.1,IF(MONTH(A11)<=10,1,IF(MONTH(A11)=11,1.05,1.2)))))) -> 0.95 | F11: 0.95 | G11: =ROUND(D11*E11*F11,0) -> 1986 | H11: 1.03 | I11: =ROUND(D11*E11*H11,0) -> 2153 | J11: =IF(AND(A11=DATE(2026,3,16),B11="C001",C11="P001"),"Promotion_Demand_Spike",IF(AND(A11=DATE(2026,6,8),B11="C002",C11="P004"),"Under_Forecast",IF(AND(A11=DATE(2026,7,20),B11="C003",C11="P003"),"Over_Forecast","Normal"))) -> Normal | K11: =IF(J11="Promotion_Demand_Spike",ROUND(G11*1.35,0),IF(J11="Under_Forecast",ROUND(I11*1.25,0),IF(J11="Over_Forecast",ROUND(I11*0.72,0),G11))) -> 1986 | L11: =K11-I11 -> -167 | M11: =IF(I11=0,0,L11/I11) -> -0.077566187 | N11: =ABS(L11) -> 167
A12: {=INDEX(tblWeeks[Week_Start],INT((ROW()-2)/20)+1)} -> 46027 | B12: {=INDEX(tblDemandAssumptions[Customer_ID],MOD(ROW()-2,20)+1)} -> C003 | C12: {=INDEX(tblDemandAssumptions[Product_ID],MOD(ROW()-2,20)+1)} -> P001 | D12: {=INDEX(tblDemandAssumptions[Baseline_Weekly_Qty],MOD(ROW()-2,20)+1)} -> 3000 | E12: =IF(MONTH(A12)<=2,0.95,IF(MONTH(A12)<=4,1,IF(MONTH(A12)<=6,1.05,IF(MONTH(A12)<=8,1.1,IF(MONTH(A12)<=10,1,IF(MONTH(A12)=11,1.05,1.2)))))) -> 0.95 | F12: 0.97 | G12: =ROUND(D12*E12*F12,0) -> 2765 | H12: 0.98 | I12: =ROUND(D12*E12*H12,0) -> 2793 | J12: =IF(AND(A12=DATE(2026,3,16),B12="C001",C12="P001"),"Promotion_Demand_Spike",IF(AND(A12=DATE(2026,6,8),B12="C002",C12="P004"),"Under_Forecast",IF(AND(A12=DATE(2026,7,20),B12="C003",C12="P003"),"Over_Forecast","Normal"))) -> Normal | K12: =IF(J12="Promotion_Demand_Spike",ROUND(G12*1.35,0),IF(J12="Under_Forecast",ROUND(I12*1.25,0),IF(J12="Over_Forecast",ROUND(I12*0.72,0),G12))) -> 2765 | L12: =K12-I12 -> -28 | M12: =IF(I12=0,0,L12/I12) -> -0.010025063 | N12: =ABS(L12) -> 28
A13: {=INDEX(tblWeeks[Week_Start],INT((ROW()-2)/20)+1)} -> 46027 | B13: {=INDEX(tblDemandAssumptions[Customer_ID],MOD(ROW()-2,20)+1)} -> C003 | C13: {=INDEX(tblDemandAssumptions[Product_ID],MOD(ROW()-2,20)+1)} -> P002 | D13: {=INDEX(tblDemandAssumptions[Baseline_Weekly_Qty],MOD(ROW()-2,20)+1)} -> 2700 | E13: =IF(MONTH(A13)<=2,0.95,IF(MONTH(A13)<=4,1,IF(MONTH(A13)<=6,1.05,IF(MONTH(A13)<=8,1.1,IF(MONTH(A13)<=10,1,IF(MONTH(A13)=11,1.05,1.2)))))) -> 0.95 | F13: 1.04 | G13: =ROUND(D13*E13*F13,0) -> 2668 | H13: 0.97 | I13: =ROUND(D13*E13*H13,0) -> 2488 | J13: =IF(AND(A13=DATE(2026,3,16),B13="C001",C13="P001"),"Promotion_Demand_Spike",IF(AND(A13=DATE(2026,6,8),B13="C002",C13="P004"),"Under_Forecast",IF(AND(A13=DATE(2026,7,20),B13="C003",C13="P003"),"Over_Forecast","Normal"))) -> Normal | K13: =IF(J13="Promotion_Demand_Spike",ROUND(G13*1.35,0),IF(J13="Under_Forecast",ROUND(I13*1.25,0),IF(J13="Over_Forecast",ROUND(I13*0.72,0),G13))) -> 2668 | L13: =K13-I13 -> 180 | M13: =IF(I13=0,0,L13/I13) -> 0.072347267 | N13: =ABS(L13) -> 180
... A1041: {=INDEX(tblWeeks[Week_Start],INT((ROW()-2)/20)+1)} -> 46384 | B1041: {=INDEX(tblDemandAssumptions[Customer_ID],MOD(ROW()-2,20)+1)} -> C004 | C1041: {=INDEX(tblDemandAssumptions[Product_ID],MOD(ROW()-2,20)+1)} -> P005 | D1041: {=INDEX(tblDemandAssumptions[Baseline_Weekly_Qty],MOD(ROW()-2,20)+1)} -> 1800 | E1041: =IF(MONTH(A1041)<=2,0.95,IF(MONTH(A1041)<=4,1,IF(MONTH(A1041)<=6,1.05,IF(MONTH(A1041)<=8,1.1,IF(MONTH(A1041)<=10,1,IF(MONTH(A1041)=11,1.05,1.2)))))) -> 1.2 | F1041: 0.99 | G1041: =ROUND(D1041*E1041*F1041,0) -> 2138 | H1041: 1 | I1041: =ROUND(D1041*E1041*H1041,0) -> 2160 | J1041: =IF(AND(A1041=DATE(2026,3,16),B1041="C001",C1041="P001"),"Promotion_Demand_Spike",IF(AND(A1041=DATE(2026,6,8),B1041="C002",C1041="P004"),"Under_Forecast",IF(AND(A1041=DATE(2026,7,20),B1041="C003",C1041="P003"),"Over_Forecast","Normal"))) -> Normal | K1041: =IF(J1041="Promotion_Demand_Spike",ROUND(G1041*1.35,0),IF(J1041="Under_Forecast",ROUND(I1041*1.25,0),IF(J1041="Over_Forecast",ROUND(I1041*0.72,0),G1041))) -> 2138 | L1041: =K1041-I1041 -> -22 | M1041: =IF(I1041=0,0,L1041/I1041) -> -0.010185185 | N1041: =ABS(L1041) -> 22

Sheet Weekly_Product_Demand
A1: Week_Start | B1: Product_ID | C1: Total_Forecast_Qty | D1: Actual_Order_Qty
A2: 46027 | B2: P001 | C2: =SUMIFS(Demand_Base!I:I,Demand_Base!A:A,A2,Demand_Base!C:C,B2) -> 13524 | D2: =SUMIFS(Demand_Base!K:K,Demand_Base!A:A,A2,Demand_Base!C:C,B2) -> 13543
A3: 46027 | B3: P002 | C3: =SUMIFS(Demand_Base!I:I,Demand_Base!A:A,A3,Demand_Base!C:C,B3) -> 11534 | D3: =SUMIFS(Demand_Base!K:K,Demand_Base!A:A,A3,Demand_Base!C:C,B3) -> 12020
A4: 46027 | B4: P003 | C4: =SUMIFS(Demand_Base!I:I,Demand_Base!A:A,A4,Demand_Base!C:C,B4) -> 10437 | D4: =SUMIFS(Demand_Base!K:K,Demand_Base!A:A,A4,Demand_Base!C:C,B4) -> 10111
A5: 46027 | B5: P004 | C5: =SUMIFS(Demand_Base!I:I,Demand_Base!A:A,A5,Demand_Base!C:C,B5) -> 10816 | D5: =SUMIFS(Demand_Base!K:K,Demand_Base!A:A,A5,Demand_Base!C:C,B5) -> 10655
A6: 46027 | B6: P005 | C6: =SUMIFS(Demand_Base!I:I,Demand_Base!A:A,A6,Demand_Base!C:C,B6) -> 8345 | D6: =SUMIFS(Demand_Base!K:K,Demand_Base!A:A,A6,Demand_Base!C:C,B6) -> 8159
A7: 46034 | B7: P001 | C7: =SUMIFS(Demand_Base!I:I,Demand_Base!A:A,A7,Demand_Base!C:C,B7) -> 13653 | D7: =SUMIFS(Demand_Base!K:K,Demand_Base!A:A,A7,Demand_Base!C:C,B7) -> 13623
A8: 46034 | B8: P002 | C8: =SUMIFS(Demand_Base!I:I,Demand_Base!A:A,A8,Demand_Base!C:C,B8) -> 11939 | D8: =SUMIFS(Demand_Base!K:K,Demand_Base!A:A,A8,Demand_Base!C:C,B8) -> 11767
A9: 46034 | B9: P003 | C9: =SUMIFS(Demand_Base!I:I,Demand_Base!A:A,A9,Demand_Base!C:C,B9) -> 10548 | D9: =SUMIFS(Demand_Base!K:K,Demand_Base!A:A,A9,Demand_Base!C:C,B9) -> 10325
A10: 46034 | B10: P004 | C10: =SUMIFS(Demand_Base!I:I,Demand_Base!A:A,A10,Demand_Base!C:C,B10) -> 11145 | D10: =SUMIFS(Demand_Base!K:K,Demand_Base!A:A,A10,Demand_Base!C:C,B10) -> 10718
A11: 46034 | B11: P005 | C11: =SUMIFS(Demand_Base!I:I,Demand_Base!A:A,A11,Demand_Base!C:C,B11) -> 8222 | D11: =SUMIFS(Demand_Base!K:K,Demand_Base!A:A,A11,Demand_Base!C:C,B11) -> 8176
A12: 46041 | B12: P001 | C12: =SUMIFS(Demand_Base!I:I,Demand_Base!A:A,A12,Demand_Base!C:C,B12) -> 13660 | D12: =SUMIFS(Demand_Base!K:K,Demand_Base!A:A,A12,Demand_Base!C:C,B12) -> 13704
A13: 46041 | B13: P002 | C13: =SUMIFS(Demand_Base!I:I,Demand_Base!A:A,A13,Demand_Base!C:C,B13) -> 11631 | D13: =SUMIFS(Demand_Base!K:K,Demand_Base!A:A,A13,Demand_Base!C:C,B13) -> 11540
... A261: 46384 | B261: P005 | C261: =SUMIFS(Demand_Base!I:I,Demand_Base!A:A,A261,Demand_Base!C:C,B261) -> 10413 | D261: =SUMIFS(Demand_Base!K:K,Demand_Base!A:A,A261,Demand_Base!C:C,B261) -> 10617

Sheet Weekly_Inventory_Flow
A1: Week_Start | B1: Product_ID | C1: Opening_Physical_Stock | D1: Blocked_Stock | E1: Usable_Opening_Stock | F1: Total_Actual_Order_Qty | G1: Target_Closing_Stock | H1: Net_Production_Requirement | I1: Planned_Production_Qty | J1: Projected_Closing_Stock | K1: Production_Performance_Factor | L1: Actual_Production_Qty | M1: Stock_Balance_Before_Floor | N1: Shortage_Qty | O1: Actual_Closing_Stock | P1: Production_Variance | Q1: Production_Attainment_% | R1: Line_ID | S1: Stock_Cover_Days | T1: Inventory_Risk_Status
A2: =Weekly_Product_Demand!A2 -> 46027 | B2: =Weekly_Product_Demand!B2 -> P001 | C2: 7200 | D2: 200 | E2: =C2-D2 -> 7000 | F2: =SUMIFS(Weekly_Product_Demand!$D:$D,Weekly_Product_Demand!$A:$A,A2,Weekly_Product_Demand!$B:$B,B2) -> 13543 | G2: =ROUND(F2/7*2,0) -> 3869 | H2: =MAX(0,F2+G2-E2) -> 10412 | I2: =CEILING(H2,100) -> 10500 | J2: =E2+I2-F2 -> 3957 | K2: 0.97 | L2: =ROUND(I2*K2,0) -> 10185 | M2: =E2+L2-F2 -> 3642 | N2: =MAX(0,-M2) -> 0 | O2: =MAX(0,M2) -> 3642 | P2: =L2-I2 -> -315 | Q2: =IF(I2=0,0,L2/I2) -> 0.97 | R2: =_xlfn.XLOOKUP(B2,Product_Line_Map!$A$2:$A$6,Product_Line_Map!$B$2:$B$6,"") -> L01 | S2: =IF(F2=0,0,O2/(F2/7)) -> 1.8824485 | T2: =IF(N2>0,"STOCKOUT",IF(S2<1,"CRITICAL LOW COVER",IF(S2<2,"LOW COVER","OK"))) -> LOW COVER
A3: =Weekly_Product_Demand!A3 -> 46027 | B3: =Weekly_Product_Demand!B3 -> P002 | C3: 6100 | D3: 100 | E3: =C3-D3 -> 6000 | F3: =SUMIFS(Weekly_Product_Demand!$D:$D,Weekly_Product_Demand!$A:$A,A3,Weekly_Product_Demand!$B:$B,B3) -> 12020 | G3: =ROUND(F3/7*2,0) -> 3434 | H3: =MAX(0,F3+G3-E3) -> 9454 | I3: =CEILING(H3,100) -> 9500 | J3: =E3+I3-F3 -> 3480 | K3: 1 | L3: =ROUND(I3*K3,0) -> 9500 | M3: =E3+L3-F3 -> 3480 | N3: =MAX(0,-M3) -> 0 | O3: =MAX(0,M3) -> 3480 | P3: =L3-I3 -> 0 | Q3: =IF(I3=0,0,L3/I3) -> 1 | R3: =_xlfn.XLOOKUP(B3,Product_Line_Map!$A$2:$A$6,Product_Line_Map!$B$2:$B$6,"") -> L02 | S3: =IF(F3=0,0,O3/(F3/7)) -> 2.0266223 | T3: =IF(N3>0,"STOCKOUT",IF(S3<1,"CRITICAL LOW COVER",IF(S3<2,"LOW COVER","OK"))) -> OK
A4: =Weekly_Product_Demand!A4 -> 46027 | B4: =Weekly_Product_Demand!B4 -> P003 | C4: 4800 | D4: 0 | E4: =C4-D4 -> 4800 | F4: =SUMIFS(Weekly_Product_Demand!$D:$D,Weekly_Product_Demand!$A:$A,A4,Weekly_Product_Demand!$B:$B,B4) -> 10111 | G4: =ROUND(F4/7*2,0) -> 2889 | H4: =MAX(0,F4+G4-E4) -> 8200 | I4: =CEILING(H4,100) -> 8200 | J4: =E4+I4-F4 -> 2889 | K4: 0.97 | L4: =ROUND(I4*K4,0) -> 7954 | M4: =E4+L4-F4 -> 2643 | N4: =MAX(0,-M4) -> 0 | O4: =MAX(0,M4) -> 2643 | P4: =L4-I4 -> -246 | Q4: =IF(I4=0,0,L4/I4) -> 0.97 | R4: =_xlfn.XLOOKUP(B4,Product_Line_Map!$A$2:$A$6,Product_Line_Map!$B$2:$B$6,"") -> L03 | S4: =IF(F4=0,0,O4/(F4/7)) -> 1.8297893 | T4: =IF(N4>0,"STOCKOUT",IF(S4<1,"CRITICAL LOW COVER",IF(S4<2,"LOW COVER","OK"))) -> LOW COVER
A5: =Weekly_Product_Demand!A5 -> 46027 | B5: =Weekly_Product_Demand!B5 -> P004 | C5: 5200 | D5: 300 | E5: =C5-D5 -> 4900 | F5: =SUMIFS(Weekly_Product_Demand!$D:$D,Weekly_Product_Demand!$A:$A,A5,Weekly_Product_Demand!$B:$B,B5) -> 10655 | G5: =ROUND(F5/7*2,0) -> 3044 | H5: =MAX(0,F5+G5-E5) -> 8799 | I5: =CEILING(H5,100) -> 8800 | J5: =E5+I5-F5 -> 3045 | K5: 1 | L5: =ROUND(I5*K5,0) -> 8800 | M5: =E5+L5-F5 -> 3045 | N5: =MAX(0,-M5) -> 0 | O5: =MAX(0,M5) -> 3045 | P5: =L5-I5 -> 0 | Q5: =IF(I5=0,0,L5/I5) -> 1 | R5: =_xlfn.XLOOKUP(B5,Product_Line_Map!$A$2:$A$6,Product_Line_Map!$B$2:$B$6,"") -> L02 | S5: =IF(F5=0,0,O5/(F5/7)) -> 2.0004693 | T5: =IF(N5>0,"STOCKOUT",IF(S5<1,"CRITICAL LOW COVER",IF(S5<2,"LOW COVER","OK"))) -> OK
A6: =Weekly_Product_Demand!A6 -> 46027 | B6: =Weekly_Product_Demand!B6 -> P005 | C6: 3900 | D6: 100 | E6: =C6-D6 -> 3800 | F6: =SUMIFS(Weekly_Product_Demand!$D:$D,Weekly_Product_Demand!$A:$A,A6,Weekly_Product_Demand!$B:$B,B6) -> 8159 | G6: =ROUND(F6/7*2,0) -> 2331 | H6: =MAX(0,F6+G6-E6) -> 6690 | I6: =CEILING(H6,100) -> 6700 | J6: =E6+I6-F6 -> 2341 | K6: 0.99 | L6: =ROUND(I6*K6,0) -> 6633 | M6: =E6+L6-F6 -> 2274 | N6: =MAX(0,-M6) -> 0 | O6: =MAX(0,M6) -> 2274 | P6: =L6-I6 -> -67 | Q6: =IF(I6=0,0,L6/I6) -> 0.99 | R6: =_xlfn.XLOOKUP(B6,Product_Line_Map!$A$2:$A$6,Product_Line_Map!$B$2:$B$6,"") -> L03 | S6: =IF(F6=0,0,O6/(F6/7)) -> 1.9509744 | T6: =IF(N6>0,"STOCKOUT",IF(S6<1,"CRITICAL LOW COVER",IF(S6<2,"LOW COVER","OK"))) -> LOW COVER
A7: =Weekly_Product_Demand!A7 -> 46034 | B7: =Weekly_Product_Demand!B7 -> P001 | C7: =O2 -> 3642 | D7: =0 -> 0 | E7: =C7-D7 -> 3642 | F7: =SUMIFS(Weekly_Product_Demand!$D:$D,Weekly_Product_Demand!$A:$A,A7,Weekly_Product_Demand!$B:$B,B7) -> 13623 | G7: =ROUND(F7/7*2,0) -> 3892 | H7: =MAX(0,F7+G7-E7) -> 13873 | I7: =CEILING(H7,100) -> 13900 | J7: =E7+I7-F7 -> 3919 | K7: 1 | L7: =ROUND(I7*K7,0) -> 13900 | M7: =E7+L7-F7 -> 3919 | N7: =MAX(0,-M7) -> 0 | O7: =MAX(0,M7) -> 3919 | P7: =L7-I7 -> 0 | Q7: =IF(I7=0,0,L7/I7) -> 1 | R7: =_xlfn.XLOOKUP(B7,Product_Line_Map!$A$2:$A$6,Product_Line_Map!$B$2:$B$6,"") -> L01 | S7: =IF(F7=0,0,O7/(F7/7)) -> 2.0137268 | T7: =IF(N7>0,"STOCKOUT",IF(S7<1,"CRITICAL LOW COVER",IF(S7<2,"LOW COVER","OK"))) -> OK
A8: =Weekly_Product_Demand!A8 -> 46034 | B8: =Weekly_Product_Demand!B8 -> P002 | C8: =O3 -> 3480 | D8: =0 -> 0 | E8: =C8-D8 -> 3480 | F8: =SUMIFS(Weekly_Product_Demand!$D:$D,Weekly_Product_Demand!$A:$A,A8,Weekly_Product_Demand!$B:$B,B8) -> 11767 | G8: =ROUND(F8/7*2,0) -> 3362 | H8: =MAX(0,F8+G8-E8) -> 11649 | I8: =CEILING(H8,100) -> 11700 | J8: =E8+I8-F8 -> 3413 | K8: 0.97 | L8: =ROUND(I8*K8,0) -> 11349 | M8: =E8+L8-F8 -> 3062 | N8: =MAX(0,-M8) -> 0 | O8: =MAX(0,M8) -> 3062 | P8: =L8-I8 -> -351 | Q8: =IF(I8=0,0,L8/I8) -> 0.97 | R8: =_xlfn.XLOOKUP(B8,Product_Line_Map!$A$2:$A$6,Product_Line_Map!$B$2:$B$6,"") -> L02 | S8: =IF(F8=0,0,O8/(F8/7)) -> 1.8215348 | T8: =IF(N8>0,"STOCKOUT",IF(S8<1,"CRITICAL LOW COVER",IF(S8<2,"LOW COVER","OK"))) -> LOW COVER
A9: =Weekly_Product_Demand!A9 -> 46034 | B9: =Weekly_Product_Demand!B9 -> P003 | C9: =O4 -> 2643 | D9: =0 -> 0 | E9: =C9-D9 -> 2643 | F9: =SUMIFS(Weekly_Product_Demand!$D:$D,Weekly_Product_Demand!$A:$A,A9,Weekly_Product_Demand!$B:$B,B9) -> 10325 | G9: =ROUND(F9/7*2,0) -> 2950 | H9: =MAX(0,F9+G9-E9) -> 10632 | I9: =CEILING(H9,100) -> 10700 | J9: =E9+I9-F9 -> 3018 | K9: 1.01 | L9: =ROUND(I9*K9,0) -> 10807 | M9: =E9+L9-F9 -> 3125 | N9: =MAX(0,-M9) -> 0 | O9: =MAX(0,M9) -> 3125 | P9: =L9-I9 -> 107 | Q9: =IF(I9=0,0,L9/I9) -> 1.01 | R9: =_xlfn.XLOOKUP(B9,Product_Line_Map!$A$2:$A$6,Product_Line_Map!$B$2:$B$6,"") -> L03 | S9: =IF(F9=0,0,O9/(F9/7)) -> 2.1186441 | T9: =IF(N9>0,"STOCKOUT",IF(S9<1,"CRITICAL LOW COVER",IF(S9<2,"LOW COVER","OK"))) -> OK
A10: =Weekly_Product_Demand!A10 -> 46034 | B10: =Weekly_Product_Demand!B10 -> P004 | C10: =O5 -> 3045 | D10: =0 -> 0 | E10: =C10-D10 -> 3045 | F10: =SUMIFS(Weekly_Product_Demand!$D:$D,Weekly_Product_Demand!$A:$A,A10,Weekly_Product_Demand!$B:$B,B10) -> 10718 | G10: =ROUND(F10/7*2,0) -> 3062 | H10: =MAX(0,F10+G10-E10) -> 10735 | I10: =CEILING(H10,100) -> 10800 | J10: =E10+I10-F10 -> 3127 | K10: 0.97 | L10: =ROUND(I10*K10,0) -> 10476 | M10: =E10+L10-F10 -> 2803 | N10: =MAX(0,-M10) -> 0 | O10: =MAX(0,M10) -> 2803 | P10: =L10-I10 -> -324 | Q10: =IF(I10=0,0,L10/I10) -> 0.97 | R10: =_xlfn.XLOOKUP(B10,Product_Line_Map!$A$2:$A$6,Product_Line_Map!$B$2:$B$6,"") -> L02 | S10: =IF(F10=0,0,O10/(F10/7)) -> 1.8306587 | T10: =IF(N10>0,"STOCKOUT",IF(S10<1,"CRITICAL LOW COVER",IF(S10<2,"LOW COVER","OK"))) -> LOW COVER
A11: =Weekly_Product_Demand!A11 -> 46034 | B11: =Weekly_Product_Demand!B11 -> P005 | C11: =O6 -> 2274 | D11: =0 -> 0 | E11: =C11-D11 -> 2274 | F11: =SUMIFS(Weekly_Product_Demand!$D:$D,Weekly_Product_Demand!$A:$A,A11,Weekly_Product_Demand!$B:$B,B11) -> 8176 | G11: =ROUND(F11/7*2,0) -> 2336 | H11: =MAX(0,F11+G11-E11) -> 8238 | I11: =CEILING(H11,100) -> 8300 | J11: =E11+I11-F11 -> 2398 | K11: 1.02 | L11: =ROUND(I11*K11,0) -> 8466 | M11: =E11+L11-F11 -> 2564 | N11: =MAX(0,-M11) -> 0 | O11: =MAX(0,M11) -> 2564 | P11: =L11-I11 -> 166 | Q11: =IF(I11=0,0,L11/I11) -> 1.02 | R11: =_xlfn.XLOOKUP(B11,Product_Line_Map!$A$2:$A$6,Product_Line_Map!$B$2:$B$6,"") -> L03 | S11: =IF(F11=0,0,O11/(F11/7)) -> 2.1952055 | T11: =IF(N11>0,"STOCKOUT",IF(S11<1,"CRITICAL LOW COVER",IF(S11<2,"LOW COVER","OK"))) -> OK
A12: =Weekly_Product_Demand!A12 -> 46041 | B12: =Weekly_Product_Demand!B12 -> P001 | C12: =O7 -> 3919 | D12: =0 -> 0 | E12: =C12-D12 -> 3919 | F12: =SUMIFS(Weekly_Product_Demand!$D:$D,Weekly_Product_Demand!$A:$A,A12,Weekly_Product_Demand!$B:$B,B12) -> 13704 | G12: =ROUND(F12/7*2,0) -> 3915 | H12: =MAX(0,F12+G12-E12) -> 13700 | I12: =CEILING(H12,100) -> 13700 | J12: =E12+I12-F12 -> 3915 | K12: 1.01 | L12: =ROUND(I12*K12,0) -> 13837 | M12: =E12+L12-F12 -> 4052 | N12: =MAX(0,-M12) -> 0 | O12: =MAX(0,M12) -> 4052 | P12: =L12-I12 -> 137 | Q12: =IF(I12=0,0,L12/I12) -> 1.01 | R12: =_xlfn.XLOOKUP(B12,Product_Line_Map!$A$2:$A$6,Product_Line_Map!$B$2:$B$6,"") -> L01 | S12: =IF(F12=0,0,O12/(F12/7)) -> 2.0697607 | T12: =IF(N12>0,"STOCKOUT",IF(S12<1,"CRITICAL LOW COVER",IF(S12<2,"LOW COVER","OK"))) -> OK
A13: =Weekly_Product_Demand!A13 -> 46041 | B13: =Weekly_Product_Demand!B13 -> P002 | C13: =O8 -> 3062 | D13: =0 -> 0 | E13: =C13-D13 -> 3062 | F13: =SUMIFS(Weekly_Product_Demand!$D:$D,Weekly_Product_Demand!$A:$A,A13,Weekly_Product_Demand!$B:$B,B13) -> 11540 | G13: =ROUND(F13/7*2,0) -> 3297 | H13: =MAX(0,F13+G13-E13) -> 11775 | I13: =CEILING(H13,100) -> 11800 | J13: =E13+I13-F13 -> 3322 | K13: 1.02 | L13: =ROUND(I13*K13,0) -> 12036 | M13: =E13+L13-F13 -> 3558 | N13: =MAX(0,-M13) -> 0 | O13: =MAX(0,M13) -> 3558 | P13: =L13-I13 -> 236 | Q13: =IF(I13=0,0,L13/I13) -> 1.02 | R13: =_xlfn.XLOOKUP(B13,Product_Line_Map!$A$2:$A$6,Product_Line_Map!$B$2:$B$6,"") -> L02 | S13: =IF(F13=0,0,O13/(F13/7)) -> 2.1582322 | T13: =IF(N13>0,"STOCKOUT",IF(S13<1,"CRITICAL LOW COVER",IF(S13<2,"LOW COVER","OK"))) -> OK
A14: =Weekly_Product_Demand!A14 -> 46041 | B14: =Weekly_Product_Demand!B14 -> P003 | C14: =O9 -> 3125 | D14: =0 -> 0 | E14: =C14-D14 -> 3125 | F14: =SUMIFS(Weekly_Product_Demand!$D:$D,Weekly_Product_Demand!$A:$A,A14,Weekly_Product_Demand!$B:$B,B14) -> 10363 | G14: =ROUND(F14/7*2,0) -> 2961 | H14: =MAX(0,F14+G14-E14) -> 10199 | I14: =CEILING(H14,100) -> 10200 | J14: =E14+I14-F14 -> 2962 | K14: 0.99 | L14: =ROUND(I14*K14,0) -> 10098 | M14: =E14+L14-F14 -> 2860 | N14: =MAX(0,-M14) -> 0 | O14: =MAX(0,M14) -> 2860 | P14: =L14-I14 -> -102 | Q14: =IF(I14=0,0,L14/I14) -> 0.99 | R14: =_xlfn.XLOOKUP(B14,Product_Line_Map!$A$2:$A$6,Product_Line_Map!$B$2:$B$6,"") -> L03 | S14: =IF(F14=0,0,O14/(F14/7)) -> 1.931873 | T14: =IF(N14>0,"STOCKOUT",IF(S14<1,"CRITICAL LOW COVER",IF(S14<2,"LOW COVER","OK"))) -> LOW COVER
A15: =Weekly_Product_Demand!A15 -> 46041 | B15: =Weekly_Product_Demand!B15 -> P004 | C15: =O10 -> 2803 | D15: =0 -> 0 | E15: =C15-D15 -> 2803 | F15: =SUMIFS(Weekly_Product_Demand!$D:$D,Weekly_Product_Demand!$A:$A,A15,Weekly_Product_Demand!$B:$B,B15) -> 11084 | G15: =ROUND(F15/7*2,0) -> 3167 | H15: =MAX(0,F15+G15-E15) -> 11448 | I15: =CEILING(H15,100) -> 11500 | J15: =E15+I15-F15 -> 3219 | K15: 0.99 | L15: =ROUND(I15*K15,0) -> 11385 | M15: =E15+L15-F15 -> 3104 | N15: =MAX(0,-M15) -> 0 | O15: =MAX(0,M15) -> 3104 | P15: =L15-I15 -> -115 | Q15: =IF(I15=0,0,L15/I15) -> 0.99 | R15: =_xlfn.XLOOKUP(B15,Product_Line_Map!$A$2:$A$6,Product_Line_Map!$B$2:$B$6,"") -> L02 | S15: =IF(F15=0,0,O15/(F15/7)) -> 1.9603031 | T15: =IF(N15>0,"STOCKOUT",IF(S15<1,"CRITICAL LOW COVER",IF(S15<2,"LOW COVER","OK"))) -> LOW COVER
A16: =Weekly_Product_Demand!A16 -> 46041 | B16: =Weekly_Product_Demand!B16 -> P005 | C16: =O11 -> 2564 | D16: =0 -> 0 | E16: =C16-D16 -> 2564 | F16: =SUMIFS(Weekly_Product_Demand!$D:$D,Weekly_Product_Demand!$A:$A,A16,Weekly_Product_Demand!$B:$B,B16) -> 8329 | G16: =ROUND(F16/7*2,0) -> 2380 | H16: =MAX(0,F16+G16-E16) -> 8145 | I16: =CEILING(H16,100) -> 8200 | J16: =E16+I16-F16 -> 2435 | K16: 0.97 | L16: =ROUND(I16*K16,0) -> 7954 | M16: =E16+L16-F16 -> 2189 | N16: =MAX(0,-M16) -> 0 | O16: =MAX(0,M16) -> 2189 | P16: =L16-I16 -> -246 | Q16: =IF(I16=0,0,L16/I16) -> 0.97 | R16: =_xlfn.XLOOKUP(B16,Product_Line_Map!$A$2:$A$6,Product_Line_Map!$B$2:$B$6,"") -> L03 | S16: =IF(F16=0,0,O16/(F16/7)) -> 1.8397167 | T16: =IF(N16>0,"STOCKOUT",IF(S16<1,"CRITICAL LOW COVER",IF(S16<2,"LOW COVER","OK"))) -> LOW COVER
A17: =Weekly_Product_Demand!A17 -> 46048 | B17: =Weekly_Product_Demand!B17 -> P001 | C17: =O12 -> 4052 | D17: =0 -> 0 | E17: =C17-D17 -> 4052 | F17: =SUMIFS(Weekly_Product_Demand!$D:$D,Weekly_Product_Demand!$A:$A,A17,Weekly_Product_Demand!$B:$B,B17) -> 13490 | G17: =ROUND(F17/7*2,0) -> 3854 | H17: =MAX(0,F17+G17-E17) -> 13292 | I17: =CEILING(H17,100) -> 13300 | J17: =E17+I17-F17 -> 3862 | K17: 0.99 | L17: =ROUND(I17*K17,0) -> 13167 | M17: =E17+L17-F17 -> 3729 | N17: =MAX(0,-M17) -> 0 | O17: =MAX(0,M17) -> 3729 | P17: =L17-I17 -> -133 | Q17: =IF(I17=0,0,L17/I17) -> 0.99 | R17: =_xlfn.XLOOKUP(B17,Product_Line_Map!$A$2:$A$6,Product_Line_Map!$B$2:$B$6,"") -> L01 | S17: =IF(F17=0,0,O17/(F17/7)) -> 1.9349889 | T17: =IF(N17>0,"STOCKOUT",IF(S17<1,"CRITICAL LOW COVER",IF(S17<2,"LOW COVER","OK"))) -> LOW COVER
A18: =Weekly_Product_Demand!A18 -> 46048 | B18: =Weekly_Product_Demand!B18 -> P002 | C18: =O13 -> 3558 | D18: =0 -> 0 | E18: =C18-D18 -> 3558 | F18: =SUMIFS(Weekly_Product_Demand!$D:$D,Weekly_Product_Demand!$A:$A,A18,Weekly_Product_Demand!$B:$B,B18) -> 12120 | G18: =ROUND(F18/7*2,0) -> 3463 | H18: =MAX(0,F18+G18-E18) -> 12025 | I18: =CEILING(H18,100) -> 12100 | J18: =E18+I18-F18 -> 3538 | K18: 1.01 | L18: =ROUND(I18*K18,0) -> 12221 | M18: =E18+L18-F18 -> 3659 | N18: =MAX(0,-M18) -> 0 | O18: =MAX(0,M18) -> 3659 | P18: =L18-I18 -> 121 | Q18: =IF(I18=0,0,L18/I18) -> 1.01 | R18: =_xlfn.XLOOKUP(B18,Product_Line_Map!$A$2:$A$6,Product_Line_Map!$B$2:$B$6,"") -> L02 | S18: =IF(F18=0,0,O18/(F18/7)) -> 2.1132838 | T18: =IF(N18>0,"STOCKOUT",IF(S18<1,"CRITICAL LOW COVER",IF(S18<2,"LOW COVER","OK"))) -> OK
... A261: =Weekly_Product_Demand!A261 -> 46384 | B261: =Weekly_Product_Demand!B261 -> P005 | C261: =O256 -> 3025 | D261: =0 -> 0 | E261: =C261-D261 -> 3025 | F261: =SUMIFS(Weekly_Product_Demand!$D:$D,Weekly_Product_Demand!$A:$A,A261,Weekly_Product_Demand!$B:$B,B261) -> 10617 | G261: =ROUND(F261/7*2,0) -> 3033 | H261: =MAX(0,F261+G261-E261) -> 10625 | I261: =CEILING(H261,100) -> 10700 | J261: =E261+I261-F261 -> 3108 | K261: 1 | L261: =ROUND(I261*K261,0) -> 10700 | M261: =E261+L261-F261 -> 3108 | N261: =MAX(0,-M261) -> 0 | O261: =MAX(0,M261) -> 3108 | P261: =L261-I261 -> 0 | Q261: =IF(I261=0,0,L261/I261) -> 1 | R261: =_xlfn.XLOOKUP(B261,Product_Line_Map!$A$2:$A$6,Product_Line_Map!$B$2:$B$6,"") -> L03 | S261: =IF(F261=0,0,O261/(F261/7)) -> 2.0491664 | T261: =IF(N261>0,"STOCKOUT",IF(S261<1,"CRITICAL LOW COVER",IF(S261<2,"LOW COVER","OK"))) -> OK

Sheet Weekly_Material_Requirements
A1: Week_Start | B1: Product_ID | C1: Material_ID | D1: Planned_Production_Qty | E1: Qty_Per_Pack | F1: Material_Required_Qty
A2: {=INDEX(Weekly_Inventory_Flow!$A$2:$A$261,INT((ROW()-2)/4)+1)} -> 46027 | B2: {=INDEX(Weekly_Inventory_Flow!$B$2:$B$261,INT((ROW()-2)/4)+1)} -> P001 | C2: {=INDEX(BOM!$B$2:$B$21,MATCH(B2,BOM!$A$2:$A$21,0)+MOD(ROW()-2,4))} -> M001 | D2: {=INDEX(Weekly_Inventory_Flow!$I$2:$I$261,INT((ROW()-2)/4)+1)} -> 10500 | E2: {=INDEX(BOM!$C$2:$C$21,MATCH(B2,BOM!$A$2:$A$21,0)+MOD(ROW()-2,4))} -> 0.35 | F2: =D2*E2 -> 3675
A3: {=INDEX(Weekly_Inventory_Flow!$A$2:$A$261,INT((ROW()-2)/4)+1)} -> 46027 | B3: {=INDEX(Weekly_Inventory_Flow!$B$2:$B$261,INT((ROW()-2)/4)+1)} -> P001 | C3: {=INDEX(BOM!$B$2:$B$21,MATCH(B3,BOM!$A$2:$A$21,0)+MOD(ROW()-2,4))} -> M006 | D3: {=INDEX(Weekly_Inventory_Flow!$I$2:$I$261,INT((ROW()-2)/4)+1)} -> 10500 | E3: {=INDEX(BOM!$C$2:$C$21,MATCH(B3,BOM!$A$2:$A$21,0)+MOD(ROW()-2,4))} -> 0.01 | F3: =D3*E3 -> 105
A4: {=INDEX(Weekly_Inventory_Flow!$A$2:$A$261,INT((ROW()-2)/4)+1)} -> 46027 | B4: {=INDEX(Weekly_Inventory_Flow!$B$2:$B$261,INT((ROW()-2)/4)+1)} -> P001 | C4: {=INDEX(BOM!$B$2:$B$21,MATCH(B4,BOM!$A$2:$A$21,0)+MOD(ROW()-2,4))} -> M007 | D4: {=INDEX(Weekly_Inventory_Flow!$I$2:$I$261,INT((ROW()-2)/4)+1)} -> 10500 | E4: {=INDEX(BOM!$C$2:$C$21,MATCH(B4,BOM!$A$2:$A$21,0)+MOD(ROW()-2,4))} -> 1 | F4: =D4*E4 -> 10500
A5: {=INDEX(Weekly_Inventory_Flow!$A$2:$A$261,INT((ROW()-2)/4)+1)} -> 46027 | B5: {=INDEX(Weekly_Inventory_Flow!$B$2:$B$261,INT((ROW()-2)/4)+1)} -> P001 | C5: {=INDEX(BOM!$B$2:$B$21,MATCH(B5,BOM!$A$2:$A$21,0)+MOD(ROW()-2,4))} -> M008 | D5: {=INDEX(Weekly_Inventory_Flow!$I$2:$I$261,INT((ROW()-2)/4)+1)} -> 10500 | E5: {=INDEX(BOM!$C$2:$C$21,MATCH(B5,BOM!$A$2:$A$21,0)+MOD(ROW()-2,4))} -> 1 | F5: =D5*E5 -> 10500
A6: {=INDEX(Weekly_Inventory_Flow!$A$2:$A$261,INT((ROW()-2)/4)+1)} -> 46027 | B6: {=INDEX(Weekly_Inventory_Flow!$B$2:$B$261,INT((ROW()-2)/4)+1)} -> P002 | C6: {=INDEX(BOM!$B$2:$B$21,MATCH(B6,BOM!$A$2:$A$21,0)+MOD(ROW()-2,4))} -> M002 | D6: {=INDEX(Weekly_Inventory_Flow!$I$2:$I$261,INT((ROW()-2)/4)+1)} -> 9500 | E6: {=INDEX(BOM!$C$2:$C$21,MATCH(B6,BOM!$A$2:$A$21,0)+MOD(ROW()-2,4))} -> 0.3 | F6: =D6*E6 -> 2850
A7: {=INDEX(Weekly_Inventory_Flow!$A$2:$A$261,INT((ROW()-2)/4)+1)} -> 46027 | B7: {=INDEX(Weekly_Inventory_Flow!$B$2:$B$261,INT((ROW()-2)/4)+1)} -> P002 | C7: {=INDEX(BOM!$B$2:$B$21,MATCH(B7,BOM!$A$2:$A$21,0)+MOD(ROW()-2,4))} -> M006 | D7: {=INDEX(Weekly_Inventory_Flow!$I$2:$I$261,INT((ROW()-2)/4)+1)} -> 9500 | E7: {=INDEX(BOM!$C$2:$C$21,MATCH(B7,BOM!$A$2:$A$21,0)+MOD(ROW()-2,4))} -> 0.008 | F7: =D7*E7 -> 76
A8: {=INDEX(Weekly_Inventory_Flow!$A$2:$A$261,INT((ROW()-2)/4)+1)} -> 46027 | B8: {=INDEX(Weekly_Inventory_Flow!$B$2:$B$261,INT((ROW()-2)/4)+1)} -> P002 | C8: {=INDEX(BOM!$B$2:$B$21,MATCH(B8,BOM!$A$2:$A$21,0)+MOD(ROW()-2,4))} -> M007 | D8: {=INDEX(Weekly_Inventory_Flow!$I$2:$I$261,INT((ROW()-2)/4)+1)} -> 9500 | E8: {=INDEX(BOM!$C$2:$C$21,MATCH(B8,BOM!$A$2:$A$21,0)+MOD(ROW()-2,4))} -> 1 | F8: =D8*E8 -> 9500
A9: {=INDEX(Weekly_Inventory_Flow!$A$2:$A$261,INT((ROW()-2)/4)+1)} -> 46027 | B9: {=INDEX(Weekly_Inventory_Flow!$B$2:$B$261,INT((ROW()-2)/4)+1)} -> P002 | C9: {=INDEX(BOM!$B$2:$B$21,MATCH(B9,BOM!$A$2:$A$21,0)+MOD(ROW()-2,4))} -> M008 | D9: {=INDEX(Weekly_Inventory_Flow!$I$2:$I$261,INT((ROW()-2)/4)+1)} -> 9500 | E9: {=INDEX(BOM!$C$2:$C$21,MATCH(B9,BOM!$A$2:$A$21,0)+MOD(ROW()-2,4))} -> 1 | F9: =D9*E9 -> 9500
A10: {=INDEX(Weekly_Inventory_Flow!$A$2:$A$261,INT((ROW()-2)/4)+1)} -> 46027 | B10: {=INDEX(Weekly_Inventory_Flow!$B$2:$B$261,INT((ROW()-2)/4)+1)} -> P003 | C10: {=INDEX(BOM!$B$2:$B$21,MATCH(B10,BOM!$A$2:$A$21,0)+MOD(ROW()-2,4))} -> M003 | D10: {=INDEX(Weekly_Inventory_Flow!$I$2:$I$261,INT((ROW()-2)/4)+1)} -> 8200 | E10: {=INDEX(BOM!$C$2:$C$21,MATCH(B10,BOM!$A$2:$A$21,0)+MOD(ROW()-2,4))} -> 0.25 | F10: =D10*E10 -> 2050
A11: {=INDEX(Weekly_Inventory_Flow!$A$2:$A$261,INT((ROW()-2)/4)+1)} -> 46027 | B11: {=INDEX(Weekly_Inventory_Flow!$B$2:$B$261,INT((ROW()-2)/4)+1)} -> P003 | C11: {=INDEX(BOM!$B$2:$B$21,MATCH(B11,BOM!$A$2:$A$21,0)+MOD(ROW()-2,4))} -> M006 | D11: {=INDEX(Weekly_Inventory_Flow!$I$2:$I$261,INT((ROW()-2)/4)+1)} -> 8200 | E11: {=INDEX(BOM!$C$2:$C$21,MATCH(B11,BOM!$A$2:$A$21,0)+MOD(ROW()-2,4))} -> 0.006 | F11: =D11*E11 -> 49.2
A12: {=INDEX(Weekly_Inventory_Flow!$A$2:$A$261,INT((ROW()-2)/4)+1)} -> 46027 | B12: {=INDEX(Weekly_Inventory_Flow!$B$2:$B$261,INT((ROW()-2)/4)+1)} -> P003 | C12: {=INDEX(BOM!$B$2:$B$21,MATCH(B12,BOM!$A$2:$A$21,0)+MOD(ROW()-2,4))} -> M007 | D12: {=INDEX(Weekly_Inventory_Flow!$I$2:$I$261,INT((ROW()-2)/4)+1)} -> 8200 | E12: {=INDEX(BOM!$C$2:$C$21,MATCH(B12,BOM!$A$2:$A$21,0)+MOD(ROW()-2,4))} -> 1 | F12: =D12*E12 -> 8200
A13: {=INDEX(Weekly_Inventory_Flow!$A$2:$A$261,INT((ROW()-2)/4)+1)} -> 46027 | B13: {=INDEX(Weekly_Inventory_Flow!$B$2:$B$261,INT((ROW()-2)/4)+1)} -> P003 | C13: {=INDEX(BOM!$B$2:$B$21,MATCH(B13,BOM!$A$2:$A$21,0)+MOD(ROW()-2,4))} -> M008 | D13: {=INDEX(Weekly_Inventory_Flow!$I$2:$I$261,INT((ROW()-2)/4)+1)} -> 8200 | E13: {=INDEX(BOM!$C$2:$C$21,MATCH(B13,BOM!$A$2:$A$21,0)+MOD(ROW()-2,4))} -> 1 | F13: =D13*E13 -> 8200
... A1041: {=INDEX(Weekly_Inventory_Flow!$A$2:$A$261,INT((ROW()-2)/4)+1)} -> 46384 | B1041: {=INDEX(Weekly_Inventory_Flow!$B$2:$B$261,INT((ROW()-2)/4)+1)} -> P005 | C1041: {=INDEX(BOM!$B$2:$B$21,MATCH(B1041,BOM!$A$2:$A$21,0)+MOD(ROW()-2,4))} -> M008 | D1041: {=INDEX(Weekly_Inventory_Flow!$I$2:$I$261,INT((ROW()-2)/4)+1)} -> 10700 | E1041: {=INDEX(BOM!$C$2:$C$21,MATCH(B1041,BOM!$A$2:$A$21,0)+MOD(ROW()-2,4))} -> 1 | F1041: =D1041*E1041 -> 10700

Sheet Weekly_Material_Summary
A1: Week_Start | B1: Material_ID | C1: Total_Material_Required_Qty
A2: {=INDEX(Calendar_Weeks!$A$2:$A$53,INT((ROW()-2)/8)+1)} -> 46027 | B2: {=INDEX(Material_Master!$A$2:$A$9,MOD(ROW()-2,8)+1)} -> M001 | C2: =SUMIFS(Weekly_Material_Requirements!$F:$F,Weekly_Material_Requirements!$A:$A,A2,Weekly_Material_Requirements!$C:$C,B2) -> 3675
A3: {=INDEX(Calendar_Weeks!$A$2:$A$53,INT((ROW()-2)/8)+1)} -> 46027 | B3: {=INDEX(Material_Master!$A$2:$A$9,MOD(ROW()-2,8)+1)} -> M002 | C3: =SUMIFS(Weekly_Material_Requirements!$F:$F,Weekly_Material_Requirements!$A:$A,A3,Weekly_Material_Requirements!$C:$C,B3) -> 2850
A4: {=INDEX(Calendar_Weeks!$A$2:$A$53,INT((ROW()-2)/8)+1)} -> 46027 | B4: {=INDEX(Material_Master!$A$2:$A$9,MOD(ROW()-2,8)+1)} -> M003 | C4: =SUMIFS(Weekly_Material_Requirements!$F:$F,Weekly_Material_Requirements!$A:$A,A4,Weekly_Material_Requirements!$C:$C,B4) -> 2050
A5: {=INDEX(Calendar_Weeks!$A$2:$A$53,INT((ROW()-2)/8)+1)} -> 46027 | B5: {=INDEX(Material_Master!$A$2:$A$9,MOD(ROW()-2,8)+1)} -> M004 | C5: =SUMIFS(Weekly_Material_Requirements!$F:$F,Weekly_Material_Requirements!$A:$A,A5,Weekly_Material_Requirements!$C:$C,B5) -> 2992
A6: {=INDEX(Calendar_Weeks!$A$2:$A$53,INT((ROW()-2)/8)+1)} -> 46027 | B6: {=INDEX(Material_Master!$A$2:$A$9,MOD(ROW()-2,8)+1)} -> M005 | C6: =SUMIFS(Weekly_Material_Requirements!$F:$F,Weekly_Material_Requirements!$A:$A,A6,Weekly_Material_Requirements!$C:$C,B6) -> 3484
A7: {=INDEX(Calendar_Weeks!$A$2:$A$53,INT((ROW()-2)/8)+1)} -> 46027 | B7: {=INDEX(Material_Master!$A$2:$A$9,MOD(ROW()-2,8)+1)} -> M006 | C7: =SUMIFS(Weekly_Material_Requirements!$F:$F,Weekly_Material_Requirements!$A:$A,A7,Weekly_Material_Requirements!$C:$C,B7) -> 389.8
A8: {=INDEX(Calendar_Weeks!$A$2:$A$53,INT((ROW()-2)/8)+1)} -> 46027 | B8: {=INDEX(Material_Master!$A$2:$A$9,MOD(ROW()-2,8)+1)} -> M007 | C8: =SUMIFS(Weekly_Material_Requirements!$F:$F,Weekly_Material_Requirements!$A:$A,A8,Weekly_Material_Requirements!$C:$C,B8) -> 43700
A9: {=INDEX(Calendar_Weeks!$A$2:$A$53,INT((ROW()-2)/8)+1)} -> 46027 | B9: {=INDEX(Material_Master!$A$2:$A$9,MOD(ROW()-2,8)+1)} -> M008 | C9: =SUMIFS(Weekly_Material_Requirements!$F:$F,Weekly_Material_Requirements!$A:$A,A9,Weekly_Material_Requirements!$C:$C,B9) -> 43700
A10: {=INDEX(Calendar_Weeks!$A$2:$A$53,INT((ROW()-2)/8)+1)} -> 46034 | B10: {=INDEX(Material_Master!$A$2:$A$9,MOD(ROW()-2,8)+1)} -> M001 | C10: =SUMIFS(Weekly_Material_Requirements!$F:$F,Weekly_Material_Requirements!$A:$A,A10,Weekly_Material_Requirements!$C:$C,B10) -> 4865
A11: {=INDEX(Calendar_Weeks!$A$2:$A$53,INT((ROW()-2)/8)+1)} -> 46034 | B11: {=INDEX(Material_Master!$A$2:$A$9,MOD(ROW()-2,8)+1)} -> M002 | C11: =SUMIFS(Weekly_Material_Requirements!$F:$F,Weekly_Material_Requirements!$A:$A,A11,Weekly_Material_Requirements!$C:$C,B11) -> 3510
A12: {=INDEX(Calendar_Weeks!$A$2:$A$53,INT((ROW()-2)/8)+1)} -> 46034 | B12: {=INDEX(Material_Master!$A$2:$A$9,MOD(ROW()-2,8)+1)} -> M003 | C12: =SUMIFS(Weekly_Material_Requirements!$F:$F,Weekly_Material_Requirements!$A:$A,A12,Weekly_Material_Requirements!$C:$C,B12) -> 2675
A13: {=INDEX(Calendar_Weeks!$A$2:$A$53,INT((ROW()-2)/8)+1)} -> 46034 | B13: {=INDEX(Material_Master!$A$2:$A$9,MOD(ROW()-2,8)+1)} -> M004 | C13: =SUMIFS(Weekly_Material_Requirements!$F:$F,Weekly_Material_Requirements!$A:$A,A13,Weekly_Material_Requirements!$C:$C,B13) -> 3672
... A417: {=INDEX(Calendar_Weeks!$A$2:$A$53,INT((ROW()-2)/8)+1)} -> 46384 | B417: {=INDEX(Material_Master!$A$2:$A$9,MOD(ROW()-2,8)+1)} -> M008 | C417: =SUMIFS(Weekly_Material_Requirements!$F:$F,Weekly_Material_Requirements!$A:$A,A417,Weekly_Material_Requirements!$C:$C,B417) -> 70300

Sheet Weekly_Material_Inventory
A1: Week_Start | B1: Material_ID | C1: Opening_Material_Stock | D1: Total_Material_Required_Qty | E1: Target_Closing_Material_Stock | F1: Planned_Receipt_Qty | G1: Receipt_Performance_Factor | H1: Actual_Receipt_Qty | I1: Available_Material_Qty | J1: Material_Balance_Before_Floor | K1: Material_Shortage_Qty | L1: Closing_Material_Stock
A2: =Weekly_Material_Summary!A2 -> 46027 | B2: =Weekly_Material_Summary!B2 -> M001 | C2: =SUMIFS(Raw_Material_Inventory!$C:$C,Raw_Material_Inventory!$A:$A,A2,Raw_Material_Inventory!$B:$B,B2) -> 4200 | D2: =Weekly_Material_Summary!C2 -> 3675 | E2: =ROUND(D2*0.25,0) -> 919 | F2: =MAX(0,ROUND(D2+E2-C2,0)) -> 394 | G2: 1.02 | H2: =ROUND(F2*G2,0) -> 402 | I2: =C2+H2 -> 4602 | J2: =I2-D2 -> 927 | K2: =MAX(0,-J2) -> 0 | L2: =MAX(0,J2) -> 927
A3: =Weekly_Material_Summary!A3 -> 46027 | B3: =Weekly_Material_Summary!B3 -> M002 | C3: =SUMIFS(Raw_Material_Inventory!$C:$C,Raw_Material_Inventory!$A:$A,A3,Raw_Material_Inventory!$B:$B,B3) -> 3100 | D3: =Weekly_Material_Summary!C3 -> 2850 | E3: =ROUND(D3*0.25,0) -> 713 | F3: =MAX(0,ROUND(D3+E3-C3,0)) -> 463 | G3: 1.01 | H3: =ROUND(F3*G3,0) -> 468 | I3: =C3+H3 -> 3568 | J3: =I3-D3 -> 718 | K3: =MAX(0,-J3) -> 0 | L3: =MAX(0,J3) -> 718
A4: =Weekly_Material_Summary!A4 -> 46027 | B4: =Weekly_Material_Summary!B4 -> M003 | C4: =SUMIFS(Raw_Material_Inventory!$C:$C,Raw_Material_Inventory!$A:$A,A4,Raw_Material_Inventory!$B:$B,B4) -> 1900 | D4: =Weekly_Material_Summary!C4 -> 2050 | E4: =ROUND(D4*0.25,0) -> 513 | F4: =MAX(0,ROUND(D4+E4-C4,0)) -> 663 | G4: 1.02 | H4: =ROUND(F4*G4,0) -> 676 | I4: =C4+H4 -> 2576 | J4: =I4-D4 -> 526 | K4: =MAX(0,-J4) -> 0 | L4: =MAX(0,J4) -> 526
A5: =Weekly_Material_Summary!A5 -> 46027 | B5: =Weekly_Material_Summary!B5 -> M004 | C5: =SUMIFS(Raw_Material_Inventory!$C:$C,Raw_Material_Inventory!$A:$A,A5,Raw_Material_Inventory!$B:$B,B5) -> 2300 | D5: =Weekly_Material_Summary!C5 -> 2992 | E5: =ROUND(D5*0.25,0) -> 748 | F5: =MAX(0,ROUND(D5+E5-C5,0)) -> 1440 | G5: 0.99 | H5: =ROUND(F5*G5,0) -> 1426 | I5: =C5+H5 -> 3726 | J5: =I5-D5 -> 734 | K5: =MAX(0,-J5) -> 0 | L5: =MAX(0,J5) -> 734
A6: =Weekly_Material_Summary!A6 -> 46027 | B6: =Weekly_Material_Summary!B6 -> M005 | C6: =SUMIFS(Raw_Material_Inventory!$C:$C,Raw_Material_Inventory!$A:$A,A6,Raw_Material_Inventory!$B:$B,B6) -> 2800 | D6: =Weekly_Material_Summary!C6 -> 3484 | E6: =ROUND(D6*0.25,0) -> 871 | F6: =MAX(0,ROUND(D6+E6-C6,0)) -> 1555 | G6: 1.01 | H6: =ROUND(F6*G6,0) -> 1571 | I6: =C6+H6 -> 4371 | J6: =I6-D6 -> 887 | K6: =MAX(0,-J6) -> 0 | L6: =MAX(0,J6) -> 887
A7: =Weekly_Material_Summary!A7 -> 46027 | B7: =Weekly_Material_Summary!B7 -> M006 | C7: =SUMIFS(Raw_Material_Inventory!$C:$C,Raw_Material_Inventory!$A:$A,A7,Raw_Material_Inventory!$B:$B,B7) -> 420 | D7: =Weekly_Material_Summary!C7 -> 389.8 | E7: =ROUND(D7*0.25,0) -> 97 | F7: =MAX(0,ROUND(D7+E7-C7,0)) -> 67 | G7: 0.98 | H7: =ROUND(F7*G7,0) -> 66 | I7: =C7+H7 -> 486 | J7: =I7-D7 -> 96.2 | K7: =MAX(0,-J7) -> 0 | L7: =MAX(0,J7) -> 96.2
A8: =Weekly_Material_Summary!A8 -> 46027 | B8: =Weekly_Material_Summary!B8 -> M007 | C8: =SUMIFS(Raw_Material_Inventory!$C:$C,Raw_Material_Inventory!$A:$A,A8,Raw_Material_Inventory!$B:$B,B8) -> 31000 | D8: =Weekly_Material_Summary!C8 -> 43700 | E8: =ROUND(D8*0.25,0) -> 10925 | F8: =MAX(0,ROUND(D8+E8-C8,0)) -> 23625 | G8: 1.01 | H8: =ROUND(F8*G8,0) -> 23861 | I8: =C8+H8 -> 54861 | J8: =I8-D8 -> 11161 | K8: =MAX(0,-J8) -> 0 | L8: =MAX(0,J8) -> 11161
A9: =Weekly_Material_Summary!A9 -> 46027 | B9: =Weekly_Material_Summary!B9 -> M008 | C9: =SUMIFS(Raw_Material_Inventory!$C:$C,Raw_Material_Inventory!$A:$A,A9,Raw_Material_Inventory!$B:$B,B9) -> 32000 | D9: =Weekly_Material_Summary!C9 -> 43700 | E9: =ROUND(D9*0.25,0) -> 10925 | F9: =MAX(0,ROUND(D9+E9-C9,0)) -> 22625 | G9: 1.02 | H9: =ROUND(F9*G9,0) -> 23078 | I9: =C9+H9 -> 55078 | J9: =I9-D9 -> 11378 | K9: =MAX(0,-J9) -> 0 | L9: =MAX(0,J9) -> 11378
A10: =Weekly_Material_Summary!A10 -> 46034 | B10: =Weekly_Material_Summary!B10 -> M001 | C10: =L2 -> 927 | D10: =Weekly_Material_Summary!C10 -> 4865 | E10: =ROUND(D10*0.25,0) -> 1216 | F10: =MAX(0,ROUND(D10+E10-C10,0)) -> 5154 | G10: 1.02 | H10: =ROUND(F10*G10,0) -> 5257 | I10: =C10+H10 -> 6184 | J10: =I10-D10 -> 1319 | K10: =MAX(0,-J10) -> 0 | L10: =MAX(0,J10) -> 1319
A11: =Weekly_Material_Summary!A11 -> 46034 | B11: =Weekly_Material_Summary!B11 -> M002 | C11: =L3 -> 718 | D11: =Weekly_Material_Summary!C11 -> 3510 | E11: =ROUND(D11*0.25,0) -> 878 | F11: =MAX(0,ROUND(D11+E11-C11,0)) -> 3670 | G11: 1.01 | H11: =ROUND(F11*G11,0) -> 3707 | I11: =C11+H11 -> 4425 | J11: =I11-D11 -> 915 | K11: =MAX(0,-J11) -> 0 | L11: =MAX(0,J11) -> 915
A12: =Weekly_Material_Summary!A12 -> 46034 | B12: =Weekly_Material_Summary!B12 -> M003 | C12: =L4 -> 526 | D12: =Weekly_Material_Summary!C12 -> 2675 | E12: =ROUND(D12*0.25,0) -> 669 | F12: =MAX(0,ROUND(D12+E12-C12,0)) -> 2818 | G12: 1 | H12: =ROUND(F12*G12,0) -> 2818 | I12: =C12+H12 -> 3344 | J12: =I12-D12 -> 669 | K12: =MAX(0,-J12) -> 0 | L12: =MAX(0,J12) -> 669
A13: =Weekly_Material_Summary!A13 -> 46034 | B13: =Weekly_Material_Summary!B13 -> M004 | C13: =L5 -> 734 | D13: =Weekly_Material_Summary!C13 -> 3672 | E13: =ROUND(D13*0.25,0) -> 918 | F13: =MAX(0,ROUND(D13+E13-C13,0)) -> 3856 | G13: 1 | H13: =ROUND(F13*G13,0) -> 3856 | I13: =C13+H13 -> 4590 | J13: =I13-D13 -> 918 | K13: =MAX(0,-J13) -> 0 | L13: =MAX(0,J13) -> 918
A14: =Weekly_Material_Summary!A14 -> 46034 | B14: =Weekly_Material_Summary!B14 -> M005 | C14: =L6 -> 887 | D14: =Weekly_Material_Summary!C14 -> 4316 | E14: =ROUND(D14*0.25,0) -> 1079 | F14: =MAX(0,ROUND(D14+E14-C14,0)) -> 4508 | G14: 1 | H14: =ROUND(F14*G14,0) -> 4508 | I14: =C14+H14 -> 5395 | J14: =I14-D14 -> 1079 | K14: =MAX(0,-J14) -> 0 | L14: =MAX(0,J14) -> 1079
A15: =Weekly_Material_Summary!A15 -> 46034 | B15: =Weekly_Material_Summary!B15 -> M006 | C15: =L7 -> 96.2 | D15: =Weekly_Material_Summary!C15 -> 493.6 | E15: =ROUND(D15*0.25,0) -> 123 | F15: =MAX(0,ROUND(D15+E15-C15,0)) -> 520 | G15: 0.99 | H15: =ROUND(F15*G15,0) -> 515 | I15: =C15+H15 -> 611.2 | J15: =I15-D15 -> 117.6 | K15: =MAX(0,-J15) -> 0 | L15: =MAX(0,J15) -> 117.6
A16: =Weekly_Material_Summary!A16 -> 46034 | B16: =Weekly_Material_Summary!B16 -> M007 | C16: =L8 -> 11161 | D16: =Weekly_Material_Summary!C16 -> 55400 | E16: =ROUND(D16*0.25,0) -> 13850 | F16: =MAX(0,ROUND(D16+E16-C16,0)) -> 58089 | G16: 1 | H16: =ROUND(F16*G16,0) -> 58089 | I16: =C16+H16 -> 69250 | J16: =I16-D16 -> 13850 | K16: =MAX(0,-J16) -> 0 | L16: =MAX(0,J16) -> 13850
A17: =Weekly_Material_Summary!A17 -> 46034 | B17: =Weekly_Material_Summary!B17 -> M008 | C17: =L9 -> 11378 | D17: =Weekly_Material_Summary!C17 -> 55400 | E17: =ROUND(D17*0.25,0) -> 13850 | F17: =MAX(0,ROUND(D17+E17-C17,0)) -> 57872 | G17: 0.99 | H17: =ROUND(F17*G17,0) -> 57293 | I17: =C17+H17 -> 68671 | J17: =I17-D17 -> 13271 | K17: =MAX(0,-J17) -> 0 | L17: =MAX(0,J17) -> 13271
A18: =Weekly_Material_Summary!A18 -> 46041 | B18: =Weekly_Material_Summary!B18 -> M001 | C18: =L10 -> 1319 | D18: =Weekly_Material_Summary!C18 -> 4795 | E18: =ROUND(D18*0.25,0) -> 1199 | F18: =MAX(0,ROUND(D18+E18-C18,0)) -> 4675 | G18: 0.98 | H18: =ROUND(F18*G18,0) -> 4582 | I18: =C18+H18 -> 5901 | J18: =I18-D18 -> 1106 | K18: =MAX(0,-J18) -> 0 | L18: =MAX(0,J18) -> 1106
A19: =Weekly_Material_Summary!A19 -> 46041 | B19: =Weekly_Material_Summary!B19 -> M002 | C19: =L11 -> 915 | D19: =Weekly_Material_Summary!C19 -> 3540 | E19: =ROUND(D19*0.25,0) -> 885 | F19: =MAX(0,ROUND(D19+E19-C19,0)) -> 3510 | G19: 1.01 | H19: =ROUND(F19*G19,0) -> 3545 | I19: =C19+H19 -> 4460 | J19: =I19-D19 -> 920 | K19: =MAX(0,-J19) -> 0 | L19: =MAX(0,J19) -> 920
A20: =Weekly_Material_Summary!A20 -> 46041 | B20: =Weekly_Material_Summary!B20 -> M003 | C20: =L12 -> 669 | D20: =Weekly_Material_Summary!C20 -> 2550 | E20: =ROUND(D20*0.25,0) -> 638 | F20: =MAX(0,ROUND(D20+E20-C20,0)) -> 2519 | G20: 0.99 | H20: =ROUND(F20*G20,0) -> 2494 | I20: =C20+H20 -> 3163 | J20: =I20-D20 -> 613 | K20: =MAX(0,-J20) -> 0 | L20: =MAX(0,J20) -> 613
A21: =Weekly_Material_Summary!A21 -> 46041 | B21: =Weekly_Material_Summary!B21 -> M004 | C21: =L13 -> 918 | D21: =Weekly_Material_Summary!C21 -> 3910 | E21: =ROUND(D21*0.25,0) -> 978 | F21: =MAX(0,ROUND(D21+E21-C21,0)) -> 3970 | G21: 1.02 | H21: =ROUND(F21*G21,0) -> 4049 | I21: =C21+H21 -> 4967 | J21: =I21-D21 -> 1057 | K21: =MAX(0,-J21) -> 0 | L21: =MAX(0,J21) -> 1057
... A417: =Weekly_Material_Summary!A417 -> 46384 | B417: =Weekly_Material_Summary!B417 -> M008 | C417: =L409 -> 18117 | D417: =Weekly_Material_Summary!C417 -> 70300 | E417: =ROUND(D417*0.25,0) -> 17575 | F417: =MAX(0,ROUND(D417+E417-C417,0)) -> 69758 | G417: 0.99 | H417: =ROUND(F417*G417,0) -> 69060 | I417: =C417+H417 -> 87177 | J417: =I417-D417 -> 16877 | K417: =MAX(0,-J417) -> 0 | L417: =MAX(0,J417) -> 16877

Sheet Weekly_Line_Capacity
A1: Week_Start | B1: Line_ID | C1: Planned_Production_Qty | D1: Packs_Per_Hour | E1: Required_Hours | F1: Baseline_Available_Hours | G1: Capacity_Reduction_% | H1: Effective_Available_Hours | I1: Effective_Capacity_Packs | J1: Capacity_Utilisation_% | K1: Capacity_Gap_Packs | L1: Capacity_Status
A2: {=INDEX(Calendar_Weeks!$A$2:$A$53,INT((ROW()-2)/3)+1)} -> 46027 | B2: {=INDEX(Production_Line_Master!$A$2:$A$4,MOD(ROW()-2,3)+1)} -> L01 | C2: =SUMIFS(Weekly_Inventory_Flow!$I:$I,Weekly_Inventory_Flow!$A:$A,A2,Weekly_Inventory_Flow!$R:$R,B2) -> 10500 | D2: =_xlfn.XLOOKUP(B2,Production_Line_Master!$A$2:$A$4,Production_Line_Master!$C$2:$C$4) -> 1800 | E2: =C2/D2 -> 5.8333333 | F2: =_xlfn.XLOOKUP(B2,Weekly_Capacity!$B$2:$B$4,Weekly_Capacity!$E$2:$E$4) -> 38 | G2: =IF(AND(A2=DATE(2026,11,2),B2="L02"),0.7,0) -> 0 | H2: =F2*(1-G2) -> 38 | I2: =H2*D2 -> 68400 | J2: =IF(H2=0,0,E2/H2) -> 0.15350877 | K2: =MAX(0,C2-I2) -> 0 | L2: =IF(K2>0,"OVER CAPACITY",IF(J2>=0.85,"HIGH UTILISATION","WITHIN CAPACITY")) -> WITHIN CAPACITY
A3: {=INDEX(Calendar_Weeks!$A$2:$A$53,INT((ROW()-2)/3)+1)} -> 46027 | B3: {=INDEX(Production_Line_Master!$A$2:$A$4,MOD(ROW()-2,3)+1)} -> L02 | C3: =SUMIFS(Weekly_Inventory_Flow!$I:$I,Weekly_Inventory_Flow!$A:$A,A3,Weekly_Inventory_Flow!$R:$R,B3) -> 18300 | D3: =_xlfn.XLOOKUP(B3,Production_Line_Master!$A$2:$A$4,Production_Line_Master!$C$2:$C$4) -> 1500 | E3: =C3/D3 -> 12.2 | F3: =_xlfn.XLOOKUP(B3,Weekly_Capacity!$B$2:$B$4,Weekly_Capacity!$E$2:$E$4) -> 35 | G3: =IF(AND(A3=DATE(2026,11,2),B3="L02"),0.7,0) -> 0 | H3: =F3*(1-G3) -> 35 | I3: =H3*D3 -> 52500 | J3: =IF(H3=0,0,E3/H3) -> 0.34857143 | K3: =MAX(0,C3-I3) -> 0 | L3: =IF(K3>0,"OVER CAPACITY",IF(J3>=0.85,"HIGH UTILISATION","WITHIN CAPACITY")) -> WITHIN CAPACITY
A4: {=INDEX(Calendar_Weeks!$A$2:$A$53,INT((ROW()-2)/3)+1)} -> 46027 | B4: {=INDEX(Production_Line_Master!$A$2:$A$4,MOD(ROW()-2,3)+1)} -> L03 | C4: =SUMIFS(Weekly_Inventory_Flow!$I:$I,Weekly_Inventory_Flow!$A:$A,A4,Weekly_Inventory_Flow!$R:$R,B4) -> 14900 | D4: =_xlfn.XLOOKUP(B4,Production_Line_Master!$A$2:$A$4,Production_Line_Master!$C$2:$C$4) -> 1200 | E4: =C4/D4 -> 12.416667 | F4: =_xlfn.XLOOKUP(B4,Weekly_Capacity!$B$2:$B$4,Weekly_Capacity!$E$2:$E$4) -> 35 | G4: =IF(AND(A4=DATE(2026,11,2),B4="L02"),0.7,0) -> 0 | H4: =F4*(1-G4) -> 35 | I4: =H4*D4 -> 42000 | J4: =IF(H4=0,0,E4/H4) -> 0.3547619 | K4: =MAX(0,C4-I4) -> 0 | L4: =IF(K4>0,"OVER CAPACITY",IF(J4>=0.85,"HIGH UTILISATION","WITHIN CAPACITY")) -> WITHIN CAPACITY
A5: {=INDEX(Calendar_Weeks!$A$2:$A$53,INT((ROW()-2)/3)+1)} -> 46034 | B5: {=INDEX(Production_Line_Master!$A$2:$A$4,MOD(ROW()-2,3)+1)} -> L01 | C5: =SUMIFS(Weekly_Inventory_Flow!$I:$I,Weekly_Inventory_Flow!$A:$A,A5,Weekly_Inventory_Flow!$R:$R,B5) -> 13900 | D5: =_xlfn.XLOOKUP(B5,Production_Line_Master!$A$2:$A$4,Production_Line_Master!$C$2:$C$4) -> 1800 | E5: =C5/D5 -> 7.7222222 | F5: =_xlfn.XLOOKUP(B5,Weekly_Capacity!$B$2:$B$4,Weekly_Capacity!$E$2:$E$4) -> 38 | G5: =IF(AND(A5=DATE(2026,11,2),B5="L02"),0.7,0) -> 0 | H5: =F5*(1-G5) -> 38 | I5: =H5*D5 -> 68400 | J5: =IF(H5=0,0,E5/H5) -> 0.20321637 | K5: =MAX(0,C5-I5) -> 0 | L5: =IF(K5>0,"OVER CAPACITY",IF(J5>=0.85,"HIGH UTILISATION","WITHIN CAPACITY")) -> WITHIN CAPACITY
A6: {=INDEX(Calendar_Weeks!$A$2:$A$53,INT((ROW()-2)/3)+1)} -> 46034 | B6: {=INDEX(Production_Line_Master!$A$2:$A$4,MOD(ROW()-2,3)+1)} -> L02 | C6: =SUMIFS(Weekly_Inventory_Flow!$I:$I,Weekly_Inventory_Flow!$A:$A,A6,Weekly_Inventory_Flow!$R:$R,B6) -> 22500 | D6: =_xlfn.XLOOKUP(B6,Production_Line_Master!$A$2:$A$4,Production_Line_Master!$C$2:$C$4) -> 1500 | E6: =C6/D6 -> 15 | F6: =_xlfn.XLOOKUP(B6,Weekly_Capacity!$B$2:$B$4,Weekly_Capacity!$E$2:$E$4) -> 35 | G6: =IF(AND(A6=DATE(2026,11,2),B6="L02"),0.7,0) -> 0 | H6: =F6*(1-G6) -> 35 | I6: =H6*D6 -> 52500 | J6: =IF(H6=0,0,E6/H6) -> 0.42857143 | K6: =MAX(0,C6-I6) -> 0 | L6: =IF(K6>0,"OVER CAPACITY",IF(J6>=0.85,"HIGH UTILISATION","WITHIN CAPACITY")) -> WITHIN CAPACITY
A7: {=INDEX(Calendar_Weeks!$A$2:$A$53,INT((ROW()-2)/3)+1)} -> 46034 | B7: {=INDEX(Production_Line_Master!$A$2:$A$4,MOD(ROW()-2,3)+1)} -> L03 | C7: =SUMIFS(Weekly_Inventory_Flow!$I:$I,Weekly_Inventory_Flow!$A:$A,A7,Weekly_Inventory_Flow!$R:$R,B7) -> 19000 | D7: =_xlfn.XLOOKUP(B7,Production_Line_Master!$A$2:$A$4,Production_Line_Master!$C$2:$C$4) -> 1200 | E7: =C7/D7 -> 15.833333 | F7: =_xlfn.XLOOKUP(B7,Weekly_Capacity!$B$2:$B$4,Weekly_Capacity!$E$2:$E$4) -> 35 | G7: =IF(AND(A7=DATE(2026,11,2),B7="L02"),0.7,0) -> 0 | H7: =F7*(1-G7) -> 35 | I7: =H7*D7 -> 42000 | J7: =IF(H7=0,0,E7/H7) -> 0.45238095 | K7: =MAX(0,C7-I7) -> 0 | L7: =IF(K7>0,"OVER CAPACITY",IF(J7>=0.85,"HIGH UTILISATION","WITHIN CAPACITY")) -> WITHIN CAPACITY
A8: {=INDEX(Calendar_Weeks!$A$2:$A$53,INT((ROW()-2)/3)+1)} -> 46041 | B8: {=INDEX(Production_Line_Master!$A$2:$A$4,MOD(ROW()-2,3)+1)} -> L01 | C8: =SUMIFS(Weekly_Inventory_Flow!$I:$I,Weekly_Inventory_Flow!$A:$A,A8,Weekly_Inventory_Flow!$R:$R,B8) -> 13700 | D8: =_xlfn.XLOOKUP(B8,Production_Line_Master!$A$2:$A$4,Production_Line_Master!$C$2:$C$4) -> 1800 | E8: =C8/D8 -> 7.6111111 | F8: =_xlfn.XLOOKUP(B8,Weekly_Capacity!$B$2:$B$4,Weekly_Capacity!$E$2:$E$4) -> 38 | G8: =IF(AND(A8=DATE(2026,11,2),B8="L02"),0.7,0) -> 0 | H8: =F8*(1-G8) -> 38 | I8: =H8*D8 -> 68400 | J8: =IF(H8=0,0,E8/H8) -> 0.2002924 | K8: =MAX(0,C8-I8) -> 0 | L8: =IF(K8>0,"OVER CAPACITY",IF(J8>=0.85,"HIGH UTILISATION","WITHIN CAPACITY")) -> WITHIN CAPACITY
